Workbook

Sheet L1
B2: AZƏRBAYCAN RESPUBLİKASININ MƏRKƏZİ BANKI
B4: LİKVİDLİYİN ÖRTÜLMƏ ƏMSALINA DAİR HESABAT
B6: CƏDVƏL L1 - TİTUL VƏRƏQİ
B8: Bankın adı: | C8: Bank Melli İran Bakı filialı | D8: Lisenziya nömrəsi:
B9: Hesabat tarixi:
B10: Hesabatın başa çatdırılması tarixi: | C10: =TODAY() -> 45281
B12: Hesabata məsul struktur bölmə:
B13: Hesabata məsul şəxs:
B14: Adı (soyadı, adı, atasının adı): | C14: Mirheydərov Vüqar Mirfazil oğlu
B15: Vəzifəsi: | C15: baş mühasib
B16: Elektron poçt ünvanı: | C16: v.mirheydarov@bmibaku.az
B17: Telefon nömrəsi: | C17: (+99470)3771953
B18: Hesabatı tərtib edən şəxs:
B19: Adı (soyadı, adı, atasının adı): | C19: Mirheydərov Vüqar Mirfazil oğlu
B20: Vəzifəsi: | C20: Baş Mühasib
B21: Elektron poçt ünvanı: | C21: v.mirheydarov@bmibaku.az
B22: Telefon nömrəsi: | C22: (+99470)3771953

Sheet L2
A2: СƏDVƏL L2 - YÜKSƏK KEYFİYYƏTLİ LİKVİD AKTİVLƏR
A3: A - YÜKSƏK KEYFİYYƏTLİ LİKVİD AKTİVLƏR
A4: (min manatla)
A5: Maddələr | C5: Bazar qiyməti | F5: O cümlədən, bloklaşdırılmış məbləğ | I5: Xalis Bazar qiyməti
C6: MV | D6: XV | E6: Cəmi | F6: MV | G6: XV | H6: Cəmi | I6: MV | J6: XV | K6: Cəmi
A7: 1 | C7: 2 | D7: 3 | E7: 4 | F7: 5 | G7: 6 | H7: 7 | I7: 8 | J7: 9 | K7: 10
A8: 1. Yüksək Kefiyyətli Likvid Aktivlər | B8: A1 | C8: =C21+C38 -> 0 | D8: =D21+D38 -> 0 | E8: =E21+E38 -> 0 | F8: =F21+F38 -> 0 | G8: =G21+G38 -> 0 | H8: =H21+H38 -> 0 | I8: =I21+I38 -> 0 | J8: =J21+J38 -> 0 | K8: =K21+K38 -> 0
A10: B - 1-ci QRUP YÜKSƏK KEYFİYYƏTLİ LİKVİD AKTİVLƏR
A12: Maddələr | C12: Bazar qiyməti | F12: O cümlədən, bloklaşdırılmış məbləğ | I12: Xalis Bazar qiyməti
C13: MV | D13: XV | E13: Cəmi | F13: MV | G13: XV | H13: Cəmi | I13: MV | J13: XV | K13: Cəmi
A14: 1 | C14: 2 | D14: 3 | E14: 4 | F14: 5 | G14: 6 | H14: 7 | I14: 8 | J14: 9 | K14: 10
A15: 1. Bankın kassalarında, xəzinələrində, onun nümayəndəlik, şöbə və filiallarında, bankomatlarda və digər ödəniş terminallarında, habelə yolda olan milli və sərbəst dönərli xarici valyutada olan nağd vəsaitlər | B15: B1 | E15: =C15+D15 -> 0 | F15: x | G15: x | H15: x | I15: =C15 -> 0 | J15: =D15 -> 0 | K15: =E15 -> 0
A16: 2. Mərkəzi Bankda açılmış müxbir hesabda olan vəsaitər (məcburi ehtiyatların məbləği istisna olmaqla) | B16: B2 | E16: =C16+D16 -> 0 | G16: 0 | H16: =F16+G16 -> 0 | I16: =C16-F16 -> 0 | J16: =D16-G16 -> 0 | K16: =E16-H16 -> 0
A17: 3.Azərbaycan Respublikasının milli valyutada buraxdığı dövlət istiqrazları, Mərkəzi Bank tərəfindən buraxılan qiymətli kağızlar | B17: B3 | D17: 0 | E17: =C17+D17 -> 0 | F17: 0 | G17: 0 | H17: =F17+G17 -> 0 | I17: =C17-F17 -> 0 | J17: =D17-G17 -> 0 | K17: =E17-H17 -> 0
A18: 4. beynəlxalq reytinq agentlikləri tərəfindən verilmiş minimum “AA-” ölkə borc reytinqinə (və ya buna ekvivalent digər reytinq dərəcəsinə) malik ölkələrin hökumətlərinin və ya həmin ölkələrin mərkəzi banklarının buraxdıqları qiymətli kağızlar | B18: B4 | C18: 0 | D18: 0 | E18: =C18+D18 -> 0 | F18: 0 | G18: 0 | H18: =F18+G18 -> 0 | I18: =C18-F18 -> 0 | J18: =D18-G18 -> 0 | K18: =E18-H18 -> 0
A19: 5. Fondun buraxdığı təmin edilmiş qiymətli kağızlar | B19: B5 | E19: =C19+D19 -> 0 | H19: =F19+G19 -> 0 | I19: =C19-F19 -> 0 | J19: =D19-G19 -> 0 | K19: =E19-H19 -> 0
A20: 6. Beynəlxalq reytinq agentlikləri tərəfindən verilmiş minimum “AAA” kredit reytinqinə (və ya buna ekvivalent digər reytinq dərəcəsinə) malik çoxtərəfli inkişaf bankları tərəfindən buraxılmış qiymətli kağızlar | B20: B6 | E20: =C20+D20 -> 0 | H20: =F20+G20 -> 0 | I20: =C20-F20 -> 0 | J20: =D20-G20 -> 0 | K20: =E20-H20 -> 0
A21: 7. 1-ci Qrup Yüksək Kefiyyətli Likvid Aktivlərin Məcmu Fondu | B21: B7 | C21: =C15+C16+C17+C18+C19+C20 -> 0 | D21: =D15+D16+D17+D18+D19+D20 -> 0 | E21: =C21+D21 -> 0 | F21: =F16+F17+F18+F19+F20 -> 0 | G21: =G16+G17+G18+G19+G20 -> 0 | H21: =F21+G21 -> 0 | I21: =C21-F21 -> 0 | J21: =D21-G21 -> 0 | K21: =E21-H21 -> 0
A23: C - 2-ci QRUP YÜKSƏK KEYFİYYƏTLİ LİKVİD AKTİVLƏR
A25: Maddələr | C25: Bazar qiyməti | F25: O cümlədən, bloklaşdırılmış məbləğ | I25: Xalis Bazar qiyməti
C26: MV | D26: XV | E26: Cəmi | F26: MV | G26: XV | H26: Cəmi | I26: MV | J26: XV | K26: Cəmi
A27: 1 | C27: 2 | D27: 3 | E27: 4 | F27: 5 | G27: 6 | H27: 7 | I27: 8 | J27: 9 | K27: 10
A28: 1. 2-ci Qrup A | B28: C1 | C28: =C29+C30+C31+C32+C33+C34 -> 0 | D28: =D29+D30+D31+D32+D33+D34 -> 0 | E28: =C28+D28 -> 0 | F28: =F29+F30+F31+F32+F33+F34 -> 0 | G28: =G29+G30+G31+G32+G33+G34 -> 0 | H28: =F28+G28 -> 0 | I28: =C28-F28 -> 0 | J28: =D28-G28 -> 0 | K28: =E28-H28 -> 0
A29: a) Azərbaycan Respublikasının xarici valyutada buraxdığı dövlət istiqrazları | B29: C1a | C29: 0 | D29: 0 | E29: =C29+D29 -> 0 | F29: 0 | G29: 0 | H29: =F29+G29 -> 0 | I29: =C29-F29 -> 0 | J29: =D29-G29 -> 0 | K29: =E29-H29 -> 0
A30: b) 1-ci qrup aktivlərə aid edilməyən və beynəlxalq reytinq agentlikləri tərəfindən verilmiş minimum “A-” ölkə (suveren) borc reytinqinə (və ya buna ekvivalent digər reytinq dərəcəsinə) malik ölkələrin hökumətlərinin və ya mərkəzi banklarının buraxdıqları qiymətli kağızlar | B30: C1b | E30: =C30+D30 -> 0 | H30: =F30+G30 -> 0 | I30: =C30-F30 -> 0 | J30: =D30-G30 -> 0 | K30: =E30-H30 -> 0
A31: c) Fondun buraxdığı təmin edilməmiş qiymətli kağızlar | B31: C1c | E31: =C31+D31 -> 0 | H31: =F31+G31 -> 0 | I31: =C31-F31 -> 0 | J31: =D31-G31 -> 0 | K31: =E31-H31 -> 0
A32: d) 1-ci qrup aktivlərə aid edilməyən və beynəlxalq reytinq agentlikləri tərəfindən verilmiş minimum investisiya reytinqə malik çoxtərəfli inkişaf bankları tərəfindən buraxılmış qiymətli kağızlar | B32: C1d | E32: =C32+D32 -> 0 | H32: =F32+G32 -> 0 | I32: =C32-F32 -> 0 | J32: =D32-G32 -> 0 | K32: =E32-H32 -> 0
A33: e) Beynəlxalq reytinq agentlikləri tərəfindən verilmiş minimum “AA-” kredit reytinqinə (və ya buna ekvivalent digər reytinq dərəcəsinə) malik qeyri-maliyyə institutlarının korporativ borc qiymətli kağızları | B33: C1e | E33: =C33+D33 -> 0 | H33: =F33+G33 -> 0 | I33: =C33-F33 -> 0 | J33: =D33-G33 -> 0 | K33: =E33-H33 -> 0
A34: f) dövlət zəmanəti, habelə Mərkəzi Bank tərəfindən aparılan pul siyasəti əməliyyatları üzrə təminat kimi qəbul edilən qiymətli kağızlarla qeyd-şərtsiz təmin olunmuş qeyri-maliyyə institutlarının korporativ borc qiymətli kağızları | B34: C1f | C34: 0 | D34: 0 | E34: =C34+D34 -> 0 | F34: 0 | G34: 0 | H34: =F34+G34 -> 0 | I34: =C34-F34 -> 0 | J34: =D34-G34 -> 0 | K34: =E34-H34 -> 0
A35: 2. 2-ci Qrup B | B35: C2 | C35: =C36+C37 -> 0 | D35: =D36+D37 -> 0 | E35: =C35+D35 -> 0 | F35: =F36+F37 -> 0 | G35: =G36+G37 -> 0 | H35: =F35+G35 -> 0 | I35: =C35-F35 -> 0 | J35: =D35-G35 -> 0 | K35: =E35-H35 -> 0
A36: a) 2-ci qrup A aktivlərə aid edilməyən və beynəlxalq reytinq agentlikləri tərəfindən verilmiş minimum investisiya reytinqə malik qeyri-maliyyə institutlarının korporativ borc qiymətli kağızları | B36: C2a | C36: 0 | D36: 0 | E36: =C36+D36 -> 0 | F36: 0 | G36: 0 | H36: =F36+G36 -> 0 | I36: =C36-F36 -> 0 | J36: =D36-G36 -> 0 | K36: =E36-H36 -> 0
A37: b) Azərbaycan Respublikası Maliyyə Nazirliyi tərəfindən xarici valyutada buraxılan dövlət istiqrazları ilə qeyd-şərtsiz təmin olunmuş qeyri-maliyyə institutlarının korporativ borc qiymətli kağızları | B37: C2b | C37: 0 | D37: 0 | E37: =C37+D37 -> 0 | F37: 0 | G37: 0 | H37: =F37+G37 -> 0 | I37: =C37-F37 -> 0 | J37: =D37-G37 -> 0 | K37: =E37-H37 -> 0
A38: 3. 2-ci Qrup Yüksək Kefiyyətli Likvid Aktivlərin hesablamaya daxil edilən məbləği | B38: C3 | C38: =MIN((C28*0.85+(MIN(0.5*C35,(3*C21/17)+0.15*C28,0.25*C21))),(C21)*2/3) -> 0 | D38: =MIN((D28*0.85+(MIN(0.5*D35,(3*D21/17)+0.15*D28,0.25*D21))),(D21)*2/3) -> 0 | E38: =MIN((E28*0.85+(MIN(0.5*E35,(3*E21/17)+0.15*E28,0.25*E21))),(E21)*2/3) -> 0 | F38: =MIN((F28*0.85+(MIN(0.5*F35,(3*F21/17)+0.15*F28,0.25*F21))),(F21)*2/3) -> 0 | G38: =MIN((G28*0.85+(MIN(0.5*G35,(3*G21/17)+0.15*G28,0.25*G21))),(G21)*2/3) -> 0 | H38: =MIN((H28*0.85+(MIN(0.5*H35,(3*H21/17)+0.15*H28,0.25*H21))),(H21)*2/3) -> 0 | I38: =MIN((I28*0.85+(MIN(0.5*I35,(3*I21/17)+0.15*I28,0.25*I21))),(I21)*2/3) -> 0 | J38: =MIN((J28*0.85+(MIN(0.5*J35,(3*J21/17)+0.15*J28,0.25*J21))),(J21)*2/3) -> 0 | K38: =MIN((K28*0.85+(MIN(0.5*K35,(3*K21/17)+0.15*K28,0.25*K21))),(K21)*2/3) -> 0

Sheet L3 (A)
A2: СƏDVƏL L3 (A) - PUL AXINLARI
A3: A - GÖZLƏNİLƏN CƏMİ NAĞD MƏXARİCLƏR
R4: (min manatla)
A5: Maddələr | C5: Ödəniş gününə qədər olan müddət | L5: Ehtimal olunan qaçış və ya geri çəkilmə ehtimalları
L6: Faizlə (%) | P6: Məbləğlə
C7: 30 günə qədər | F7: 30 gündən artıq | I7: Cəmi | L7: 0-30 | N7: 30 artıq | P7: Cəmi
C8: MV | D8: XV | E8: Cəmi | F8: MV | G8: XV | H8: Cəmi | I8: MV | J8: XV | K8: Cəmi | L8: MV | M8: XV | N8: MV | O8: XV | P8: MV | Q8: XV | R8: Cəmi
A9: 1 | C9: 2 | F9: 3 | I9: 4 | L9: 5 | N9: 6 | P9: 7
A10: 1. Gözlənilən Cəmi Nağd Məxariclər | B10: A1 | C10: =C25+C52+C66+C92 -> 0 | D10: =D25+D52+D66+D92 -> 0 | E10: =E25+E52+E66+E92 -> 0 | F10: =F25+F52+F92 -> 0 | G10: =G25+G52+G92 -> 0 | H10: =H25+H52+H92 -> 0 | I10: =I25+I52+I66+I92 -> 0 | J10: =J25+J52+J66+J92 -> 0 | K10: =K25+K52+K66+K92 -> 0 | L10: x | M10: x | N10: x | O10: x | P10: =P25+P52+P66+P92 -> 0 | Q10: =Q25+Q52+Q66+Q92 -> 0 | R10: =R25+R52+R66+R92 -> 0
A12: B - FİZİKİ ŞƏXSLƏRİN DEPOZİTLƏRİ
A14: Maddələr | C14: Ödəniş gününə qədər olan müddət | L14: Ehtimal olunan qaçış və ya geri çəkilmə ehtimalları
L15: Faizlə (%) | P15: Məbləğlə
C16: 30 günə qədər | F16: 30 gündən artıq | I16: Cəmi | L16: 0-30 | N16: 30 artıq | P16: Cəmi
C17: MV | D17: XV | E17: Cəmi | F17: MV | G17: XV | H17: Cəmi | I17: MV | J17: XV | K17: Cəmi | L17: MV | M17: XV | N17: MV | O17: XV | P17: MV | Q17: XV | R17: Cəmi
A18: 1 | C18: 2 | F18: 3 | I18: 4 | L18: 5 | N18: 6 | P18: 7
A19: 1. Fiziki şəxslərin tələbli depozitləri | B19: B1 | C19: =SUM(C20:C21) -> 0 | D19: =SUM(D20:D21) -> 0 | E19: =C19+D19 -> 0 | F19: x | G19: x | H19: x | I19: =C19 -> 0 | J19: =D19 -> 0 | K19: =I19+J19 -> 0 | L19: x | M19: x | N19: x | O19: x | P19: =SUM(P20:P21) -> 0 | Q19: =SUM(Q20:Q21) -> 0 | R19: =SUM(R20:R21) -> 0
A20: a) sığortalanan hissə | B20: B1a | E20: =C20+D20 -> 0 | F20: x | G20: x | H20: x | I20: =C20 -> 0 | J20: =D20 -> 0 | K20: =I20+J20 -> 0 | L20: 0.25 | M20: 0.22 | N20: x | O20: x | P20: =C20*L20 -> 0 | Q20: =D20*M20 -> 0 | R20: =P20+Q20 -> 0
A21: b) digər | B21: B1b | E21: =C21+D21 -> 0 | F21: x | G21: x | H21: x | I21: =C21 -> 0 | J21: =D21 -> 0 | K21: =I21+J21 -> 0 | L21: 0.35 | M21: 0.32 | N21: x | O21: x | P21: =C21*L21 -> 0 | Q21: =D21*M21 -> 0 | R21: =P21+Q21 -> 0
A22: 2. Fiziki şəxslərin müddətli depozitləri | B22: B2 | C22: =SUM(C23:C24) -> 0 | D22: =SUM(D23:D24) -> 0 | E22: =C22+D22 -> 0 | F22: =SUM(F23:F24) -> 0 | G22: =SUM(G23:G24) -> 0 | H22: =F22+G22 -> 0 | I22: =C22+F22 -> 0 | J22: =D22+G22 -> 0 | K22: =I22+J22 -> 0 | L22: x | M22: x | N22: x | O22: x | P22: =SUM(P23:P24) -> 0 | Q22: =SUM(Q23:Q24) -> 0 | R22: =SUM(R23:R24) -> 0
A23: a) sığortalanan hissə | B23: B2a | E23: =C23+D23 -> 0 | H23: =F23+G23 -> 0 | I23: =C23+F23 -> 0 | J23: =D23+G23 -> 0 | K23: =I23+J23 -> 0 | L23: 0.2 | M23: 0.17 | N23: 0.1 | O23: 0.07 | P23: =C23*L23+F23*N23 -> 0 | Q23: =D23*M23+G23*O23 -> 0 | R23: =P23+Q23 -> 0
A24: b) digər | B24: B2b | E24: =C24+D24 -> 0 | H24: =F24+G24 -> 0 | I24: =C24+F24 -> 0 | J24: =D24+G24 -> 0 | K24: =I24+J24 -> 0 | L24: 0.3 | M24: 0.27 | N24: 0.2 | O24: 0.17 | P24: =C24*L24+F24*N24 -> 0 | Q24: =D24*M24+G24*O24 -> 0 | R24: =P24+Q24 -> 0
A25: 3. Cəmi fiziki şəxslərin depozitləri | B25: B3 | C25: =C19+C22 -> 0 | D25: =D19+D22 -> 0 | E25: =E19+E22 -> 0 | F25: =F22 -> 0 | G25: =G22 -> 0 | H25: =H22 -> 0 | I25: =I19+I22 -> 0 | J25: =J19+J22 -> 0 | K25: =K19+K22 -> 0 | L25: x | M25: x | N25: x | O25: x | P25: =P19+P22 -> 0 | Q25: =Q19+Q22 -> 0 | R25: =R19+R22 -> 0
A27: C - HÜQUQİ ŞƏXSLƏRDƏN TƏMİNATSIZ CƏLBOLUNMALAR
A29: Maddələr | C29: Ödəniş gününə qədər olan müddət | L29: Ehtimal olunan qaçış və ya geri çəkilmə ehtimalları
L30: Faizlə (%) | P30: Məbləğlə
C31: 30 günə qədər | F31: 30 gündən artıq | I31: Cəmi | L31: 0-30 | N31: 30 artıq | P31: Cəmi
C32: MV | D32: XV | E32: Cəmi | F32: MV | G32: XV | H32: Cəmi | I32: MV | J32: XV | K32: Cəmi | L32: MV | M32: XV | N32: MV | O32: XV | P32: MV | Q32: XV | R32: Cəmi
A33: 1 | C33: 2 | F33: 3 | I33: 4 | L33: 5 | N33: 6 | P33: 7
A34: 1. Hökumətlər, Mərkəzi Banklar, Mərkəzi İdarəetmə Orqanları və Çoxtərəfli İnkişaf Banklarının vəsaitləri | B34: C1 | E34: =C34+D34 -> 0 | H34: =F34+G34 -> 0 | I34: =C34+F34 -> 0 | J34: =D34+G34 -> 0 | K34: =I34+J34 -> 0 | L34: 0.4 | M34: 0.35 | N34: 0.3 | O34: 0.2 | P34: =C34*L34+F34*N34 -> 0 | Q34: =D34*M34+G34*O34 -> 0 | R34: =P34+Q34 -> 0
A35: 2. Bankların tələbləri | B35: C2 | C35: =SUM(C36:C37) -> 0 | D35: =SUM(D36:D37) -> 0 | E35: =C35+D35 -> 0 | F35: =SUM(F36:F37) -> 0 | G35: =SUM(G36:G37) -> 0 | H35: =F35+G35 -> 0 | I35: =C35+F35 -> 0 | J35: =D35+G35 -> 0 | K35: =I35+J35 -> 0 | L35: x | M35: x | N35: x | O35: x | P35: =SUM(P36:P37) -> 0 | Q35: =SUM(Q36:Q37) -> 0 | R35: =SUM(R36:R37) -> 0
A36: a) Loro hesabları | B36: C2a | E36: =C36+D36 -> 0 | F36: x | G36: x | H36: x | I36: =C36 -> 0 | J36: =D36 -> 0 | K36: =I36+J36 -> 0 | L36: 1 | M36: 1 | N36: x | O36: x | P36: =C36*L36 -> 0 | Q36: =D36*M36 -> 0 | R36: =P36+Q36 -> 0
A37: b) Bankların depozitləri | B37: C2b | E37: =C37+D37 -> 0 | H37: =F37+G37 -> 0 | I37: =C37+F37 -> 0 | J37: =D37+G37 -> 0 | K37: =I37+J37 -> 0 | L37: 0.5 | M37: 0.4 | N37: 0.2 | O37: 0.1 | P37: =C37*L37+F37*N37 -> 0 | Q37: =D37*M37+G37*O37 -> 0 | R37: =P37+Q37 -> 0
A38: 3. Qeyri-bank maliyyə institutlarının vəsaitləri | B38: C3 | C38: =SUM(C39:C40) -> 0 | D38: =SUM(D39:D40) -> 0 | E38: =C38+D38 -> 0 | F38: =SUM(F39:F40) -> 0 | G38: =SUM(G39:G40) -> 0 | H38: =F38+G38 -> 0 | I38: =C38+F38 -> 0 | J38: =D38+G38 -> 0 | K38: =I38+J38 -> 0 | L38: x | M38: x | N38: x | O38: x | P38: =P39+P40 -> 0 | Q38: =Q39+Q40 -> 0 | R38: =R39+R40 -> 0
A39: a) Tələbli vəsaitləri | B39: C3a | E39: =C39+D39 -> 0 | F39: x | G39: x | H39: x | I39: =C39 -> 0 | J39: =D39 -> 0 | K39: =I39+J39 -> 0 | L39: 0.75 | M39: 0.75 | N39: x | O39: x | P39: =C39*L39 -> 0 | Q39: =D39*M39 -> 0 | R39: =P39+Q39 -> 0
A40: b) Müddətli vəsaitlər | B40: C3b | C40: 0 | D40: 0 | E40: =C40+D40 -> 0 | H40: =F40+G40 -> 0 | I40: =C40+F40 -> 0 | J40: =D40+G40 -> 0 | K40: =I40+J40 -> 0 | L40: 0.5 | M40: 0.4 | N40: 0.2 | O40: 0.1 | P40: =C40*L40+F40*N40 -> 0 | Q40: =D40*M40+G40*O40 -> 0 | R40: =P40+Q40 -> 0
A41: 4. Digər hüquqi şəxslərin tələbli depozitləri | B41: C4 | C41: =SUM(C42:C45) -> 0 | D41: =SUM(D42:D45) -> 0 | E41: =C41+D41 -> 0 | F41: x | G41: x | H41: x | I41: =C41 -> 0 | J41: =D41 -> 0 | K41: =I41+J41 -> 0 | L41: x | M41: x | N41: x | O41: x | P41: =SUM(P42:P45) -> 0 | Q41: =SUM(Q42:Q45) -> 0 | R41: =SUM(R42:R45) -> 0
A42: a) 100 000 manata qədər | B42: C4a | E42: =C42+D42 -> 0 | F42: x | G42: x | H42: x | I42: =C42 -> 0 | J42: =D42 -> 0 | K42: =I42+J42 -> 0 | L42: 0.2 | M42: 0.18 | N42: x | O42: x | P42: =C42*L42 -> 0 | Q42: =D42*M42 -> 0 | R42: =P42+Q42 -> 0
A43: b) 100 001- 500 000 manat | B43: C4b | E43: =C43+D43 -> 0 | F43: x | G43: x | H43: x | I43: =C43 -> 0 | J43: =D43 -> 0 | K43: =I43+J43 -> 0 | L43: 0.25 | M43: 0.23 | N43: x | O43: x | P43: =C43*L43 -> 0 | Q43: =D43*M43 -> 0 | R43: =P43+Q43 -> 0
A44: c) 500 001 – 1 000 000 manat | B44: C4c | E44: =C44+D44 -> 0 | F44: x | G44: x | H44: x | I44: =C44 -> 0 | J44: =D44 -> 0 | K44: =I44+J44 -> 0 | L44: 0.3 | M44: 0.28 | N44: x | O44: x | P44: =C44*L44 -> 0 | Q44: =D44*M44 -> 0 | R44: =P44+Q44 -> 0
A45: d) 1 000 000 manatdan yuxarı | B45: C4d | E45: =C45+D45 -> 0 | F45: x | G45: x | H45: x | I45: =C45 -> 0 | J45: =D45 -> 0 | K45: =I45+J45 -> 0 | L45: 0.35 | M45: 0.33 | N45: x | O45: x | P45: =C45*L45 -> 0 | Q45: =D45*M45 -> 0 | R45: =P45+Q45 -> 0
...

Sheet L3 (B)
A2: СƏDVƏL L3 (B) - PUL AXINLARI
A3: A - GÖZLƏNİLƏN CƏMİ NAĞD MƏDAXİLLƏR
R4: (min manatla)
A5: Maddələr | C5: Ödəniş gününə qədər olan müddət | L5: Ehtimal olunan daxilolmalar
L6: Faizlə (%) | P6: Məbləğlə
C7: 30 günə qədər | F7: 30 gündən artıq | I7: Cəmi | L7: 0-30 | N7: 30 artıq | P7: Cəmi
C8: MV | D8: XV | E8: Cəmi | F8: MV | G8: XV | H8: Cəmi | I8: MV | J8: XV | K8: Cəmi | L8: MV | M8: XV | N8: MV | O8: XV | P8: MV | Q8: XV | R8: Cəmi
A9: 1 | C9: 2 | F9: 3 | I9: 4 | L9: 5 | N9: 6 | P9: 7
A10: 1. Gözlənilən Cəmi Nağd Mədaxillər | B10: A1 | C10: =C24+C52+C39 -> 0 | D10: =D24+D52+D39 -> 0 | E10: =E24+E52+E39 -> 0 | F10: =F52 -> 0 | G10: =G52 -> 0 | H10: =H52 -> 0 | I10: =I24+I52+I39 -> 0 | J10: =J24+J52+J39 -> 0 | K10: =K24+K52+K39 -> 0 | L10: x | M10: x | N10: x | O10: x | P10: =P24+P52+P39 -> 0 | Q10: =Q24+Q52+Q39 -> 0 | R10: =R24+R52+R39 -> 0
A12: B - YERLƏŞDİRİLMİŞ VƏSAİTLƏR
A14: Maddələr | C14: Ödəniş gününə qədər olan müddət | L14: Ehtimal olunan daxilolmalar
L15: Faizlə (%) | P15: Məbləğlə
C16: 30 günə qədər | F16: 30 gündən artıq | I16: Cəmi | L16: 0-30 | N16: 30 artıq | P16: Cəmi
C17: MV | D17: XV | E17: Cəmi | F17: MV | G17: XV | H17: Cəmi | I17: MV | J17: XV | K17: Cəmi | L17: MV | M17: XV | N17: MV | O17: XV | P17: MV | Q17: XV | R17: Cəmi
A18: 1 | C18: 2 | F18: 3 | I18: 4 | L18: 5 | N18: 6 | P18: 7
A19: 1. Kreditlər üzrə ödənişlər | B19: B1 | E19: =C19+D19 -> 0 | H19: =F19+G19 -> 0 | I19: =C19+F19 -> 0 | J19: =D19+G19 -> 0 | K19: =I19+J19 -> 0 | L19: 0.5 | M19: 0.5 | N19: x | O19: x | P19: =C19*L19 -> 0 | Q19: =D19*M19 -> 0 | R19: =P19+Q19 -> 0
A20: 2. Hökumətlər, Məkəzi İdarəetmə Orqanlarından və Çoxtərəfli İnkişaf Banklarından daxilolmalar | B20: B2 | C20: 0 | D20: 0 | E20: =C20+D20 -> 0 | H20: =F20+G20 -> 0 | I20: =C20+F20 -> 0 | J20: =D20+G20 -> 0 | K20: =I20+J20 -> 0 | L20: 1 | M20: 1 | N20: x | O20: x | P20: =C20*L20 -> 0 | Q20: =D20*M20 -> 0 | R20: =P20+Q20 -> 0
A21: 3. Mərkəzi Banklardan daxilolmalar | B21: B3 | C21: 0 | D21: 0 | E21: =C21+D21 -> 0 | H21: =F21+G21 -> 0 | I21: =C21+F21 -> 0 | J21: =D21+G21 -> 0 | K21: =I21+J21 -> 0 | L21: 1 | M21: 1 | N21: x | O21: x | P21: =C21*L21 -> 0 | Q21: =D21*M21 -> 0 | R21: =P21+Q21 -> 0
A22: 4. Banklardan daxilolmalar | B22: B4 | C22: 0 | D22: 0 | E22: =C22+D22 -> 0 | H22: =F22+G22 -> 0 | I22: =C22+F22 -> 0 | J22: =D22+G22 -> 0 | K22: =I22+J22 -> 0 | L22: 1 | M22: 1 | N22: x | O22: x | P22: =C22*L22 -> 0 | Q22: =D22*M22 -> 0 | R22: =P22+Q22 -> 0
A23: 5. Qeyri-bank maliyyə institutlarından daxilolamalar | B23: B5 | C23: 0 | D23: 0 | E23: =C23+D23 -> 0 | H23: =F23+G23 -> 0 | I23: =C23+F23 -> 0 | J23: =D23+G23 -> 0 | K23: =I23+J23 -> 0 | L23: 1 | M23: 1 | N23: x | O23: x | P23: =C23*L23 -> 0 | Q23: =D23*M23 -> 0 | R23: =P23+Q23 -> 0
A24: 6. Cəmi yerləşdirilmiş vəsaitlərdən daxilolmalar | B24: B6 | C24: =SUM(C19:C23) -> 0 | D24: =SUM(D19:D23) -> 0 | E24: =C24+D24 -> 0 | F24: =SUM(F19:F23) -> 0 | G24: =SUM(G19:G23) -> 0 | H24: =F24+G24 -> 0 | I24: =C24+F24 -> 0 | J24: =D24+G24 -> 0 | K24: =I24+J24 -> 0 | L24: x | M24: x | N24: x | O24: x | P24: =SUM(P19:P23) -> 0 | Q24: =SUM(Q19:Q23) -> 0 | R24: =SUM(R19:R23) -> 0
A26: C - Təminatlı yerləşdirmələr
A28: Maddələr | C28: Ödəniş gününə qədər olan müddət | L28: Ehtimal olunan daxilolmalar
L29: Faizlə (%) | P29: Məbləğlə
C30: 30 günə qədər | F30: 30 gündən artıq | I30: Cəmi | L30: 0-30 | N30: 30 artıq | P30: Cəmi
C31: MV | D31: XV | E31: Cəmi | F31: MV | G31: XV | H31: Cəmi | I31: MV | J31: XV | K31: Cəmi | L31: MV | M31: XV | N31: MV | O31: XV | P31: MV | Q31: XV | R31: Cəmi
A32: 1 | C32: 2 | F32: 3 | I32: 4 | L32: 5 | N32: 6 | P32: 7
A33: 1. 1-ci Qrup Yüksək Keyfiyyətli Likvid Aktivlər ilə təmin olunmuş yerləşdirmələr | B33: C1 | C33: 0 | D33: 0 | E33: =C33+D33 -> 0 | F33: x | G33: x | H33: x | I33: =C33 -> 0 | J33: =D33 -> 0 | K33: =I33+J33 -> 0 | L33: 0 | M33: 0 | N33: x | O33: x | P33: =C33*L33 -> 0 | Q33: =D33*M33 -> 0 | R33: =P33+Q33 -> 0
A34: 2. 2-ci Qrup Yüksək Keyfiyyətli Likvid Aktivlər ilə təmin olunmuş yerləşdirmələr | B34: C2 | C34: =C35+C36 -> 0 | D34: =D35+D36 -> 0 | E34: =C34+D34 -> 0 | F34: x | G34: x | H34: x | I34: =C34 -> 0 | J34: =D34 -> 0 | K34: =I34+J34 -> 0 | L34: x | M34: x | N34: x | O34: x | P34: x | Q34: x | R34: x
A35: a) 2-ci qrup A aktivlər | B35: C2.1 | C35: 0 | D35: 0 | E35: =C35+D35 -> 0 | F35: x | G35: x | H35: x | I35: =C35 -> 0 | J35: =D35 -> 0 | K35: =I35+J35 -> 0 | L35: 0.15 | M35: 0.15 | N35: x | O35: x | P35: =C35*L35 -> 0 | Q35: =D35*M35 -> 0 | R35: =P35+Q35 -> 0
A36: b) 2-ci qrup B aktivlər | B36: C2.2 | C36: 0 | D36: 0 | E36: =C36+D36 -> 0 | F36: x | G36: x | H36: x | I36: =C36 -> 0 | J36: =D36 -> 0 | K36: =I36+J36 -> 0 | L36: 0.5 | M36: 0.5 | N36: x | O36: x | P36: =C36*L36 -> 0 | Q36: =D36*M36 -> 0 | R36: =P36+Q36 -> 0
A37: 3. Yüksək Keyfiyyətli Likvid Aktivlərlə təmin olunmuş, lakin bu təminatı LCR-ın surətində tanınmayan yerləşdirmələr | B37: C3 | C37: 0 | D37: 0 | E37: =C37+D37 -> 0 | F37: x | G37: x | H37: x | I37: =C37 -> 0 | J37: =D37 -> 0 | K37: =I37+J37 -> 0 | L37: 1 | M37: 1 | N37: x | O37: x | P37: =C37*L37 -> 0 | Q37: =D37*M37 -> 0 | R37: =P37+Q37 -> 0
A38: 4. Digər aktivlər ilə təmin olunmuş yerləşdirmələr | B38: C4 | C38: 0 | D38: 0 | E38: =C38+D38 -> 0 | F38: x | G38: x | H38: x | I38: =C38 -> 0 | J38: =D38 -> 0 | K38: =I38+J38 -> 0 | L38: 1 | M38: 1 | N38: x | O38: x | P38: =C38*L38 -> 0 | Q38: =D38*M38 -> 0 | R38: =P38+Q38 -> 0
A39: 5. Cəmi təminatlı yerləşdirmələr | B39: C5 | C39: =C33+C34+C38+C37 -> 0 | D39: =D33+D34+D38+D37 -> 0 | E39: =C39+D39 -> 0 | F39: x | G39: x | H39: x | I39: =C39 -> 0 | J39: =D39 -> 0 | K39: =I39+J39 -> 0 | L39: x | M39: x | N39: x | O39: x | P39: =P33+P35+P36+P38+P37 -> 0 | Q39: =Q33+Q35+Q36+Q38+Q37 -> 0 | R39: =R33+R35+R36+R38+R37 -> 0
A41: D - DİGƏR TƏLƏBLƏR
A43: Maddələr | C43: Ödəniş gününə qədər olan müddət | L43: Ehtimal olunan daxilolmalar
L44: Faizlə (%) | P44: Məbləğlə
C45: 30 günə qədər | F45: 30 gündən artıq | I45: Cəmi | L45: 0-30 | N45: 30 artıq | P45: Cəmi
C46: MV | D46: XV | E46: Cəmi | F46: MV | G46: XV | H46: Cəmi | I46: MV | J46: XV | K46: Cəmi | L46: MV | M46: XV | N46: MV | O46: XV | P46: MV | Q46: XV | R46: Cəmi
A47: 1 | C47: 2 | F47: 3 | I47: 4 | L47: 5 | N47: 6 | P47: 7
...

Sheet L4
A2: СƏDVƏL L4 - LİKVİDLİYİN ÖRTÜLMƏ ƏMSALI
A3: (min manatla)
A4: Maddələr | C4: Cəmi | D4: MV | E4: XV
A5: 1 | C5: 2
A6: 1. Likvidliyin Örtülmə Əmsalı | B6: L1 | C6: =IFERROR(C7/C10,0) -> 0 | D6: =IFERROR(D7/D10,0) -> 0 | E6: =IFERROR(E7/E10,0) -> 0
A7: 2. Yüksək Keyfiyyətli Likvid Aktivlər | B7: L2 | C7: ='L2'!K8 -> 0 | D7: ='L2'!I8 -> 0 | E7: ='L2'!J8 -> 0
A8: 3. Gözlənilən cəmi nağd ödənişlər | B8: L3 | C8: ='L3 (A)'!R10 -> 0 | D8: ='L3 (A)'!P10 -> 0 | E8: ='L3 (A)'!Q10 -> 0
A9: 4. Gözlənilən cəmi nağd daxilolmalar | B9: L4 | C9: ='L3 (B)'!R10 -> 0 | D9: ='L3 (B)'!P10 -> 0 | E9: ='L3 (B)'!Q10 -> 0
A10: 5. Cəmi xalis nağd ödənişlər | B10: L5 | C10: =C8-MIN(C9,0.75*C8) -> 0 | D10: =D8-MIN(D9,0.75*D8) -> 0 | E10: =E8-MIN(E9,0.75*E8) -> 0
