Workbook

Sheet Daily
A1: Balans məlumatları və digər maliyyə göstəricilərinin gündəlik dəyişməsi hesabatı
F3: min manatla
B4: Balans hesabatı | C4: Bank Melli İran
A5: AKTİVLƏR | C5: =RIGHT('Daily-Report'!J3,10) -> 19/01/2024 | D5: =RIGHT('Daily-Report'!A3,10) -> 22/01/2024 | E5: Fərq,%-lə | F5: Fərq məbləğlə
A6: 1 | B6: Nağd vəsaitlər | C6: ='Daily-Report'!L6 -> 0 | D6: ='Daily-Report'!C6 -> 0 | E6: =IFERROR((D6-C6)/C6*100%,0) -> 0 | F6: =D6-C6 -> 0
A7: 2 | B7: Müxbir hesablar | C7: ='Daily-Report'!L7 -> 0 | D7: ='Daily-Report'!C7 -> 0 | E7: =IFERROR((D7-C7)/C7*100%,0) -> 0 | F7: =D7-C7 -> 0
A8: 2a | B8: AMB | C8: ='Daily-Report'!L8 -> 0 | D8: ='Daily-Report'!C8 -> 0 | E8: =IFERROR((D8-C8)/C8*100%,0) -> 0 | F8: =D8-C8 -> 0
A9: 2a.1 | B9: o cümlədən blokda olan vəsaitlər | C9: ='Daily-Report'!L9 -> 0 | D9: ='Daily-Report'!C9 -> 0 | E9: =IFERROR((D9-C9)/C9*100%,0) -> 0 | F9: =D9-C9 -> 0
A10: 2b | B10: Rezident banklarda müxbir hesablar (xalis) | C10: ='Daily-Report'!L10 -> 0 | D10: ='Daily-Report'!C10 -> 0 | E10: =IFERROR((D10-C10)/C10*100%,0) -> 0 | F10: =D10-C10 -> 0
A11: 2b.1 | B11: o cümlədən blokda olan vəsaitlər | C11: ='Daily-Report'!L11 -> 0 | D11: ='Daily-Report'!C11 -> 0 | E11: =IFERROR((D11-C11)/C11*100%,0) -> 0 | F11: =D11-C11 -> 0
A12: 2c | B12: Qeyri-rezident banklarda müxbir hesablar (xalis) | C12: ='Daily-Report'!L12 -> 0 | D12: ='Daily-Report'!C12 -> 0 | E12: =IFERROR((D12-C12)/C12*100%,0) -> 0 | F12: =D12-C12 -> 0
A13: 2c.1 | B13: o cümlədən blokda olan vəsaitlər | C13: ='Daily-Report'!L13 -> 0 | D13: ='Daily-Report'!C13 -> 0 | E13: =IFERROR((D13-C13)/C13*100%,0) -> 0 | F13: =D13-C13 -> 0
A14: 3 | B14: Qiymətli kağızlar (xalis) | C14: ='Daily-Report'!L14 -> 0 | D14: ='Daily-Report'!C14 -> 0 | E14: =IFERROR((D14-C14)/C14*100%,0) -> 0 | F14: =D14-C14 -> 0
A15: 4 | B15: Banklara depozitlər və kreditlər (xalis) | C15: ='Daily-Report'!L15 -> 0 | D15: ='Daily-Report'!C15 -> 0 | E15: =IFERROR((D15-C15)/C15*100%,0) -> 0 | F15: =D15-C15 -> 0
A16: 4a | B16: Banklara depozitlər və kreditlər üzrə məqsədli ehtiyatlar | C16: ='Daily-Report'!L16 -> 0 | D16: ='Daily-Report'!C16 -> 0 | E16: =IFERROR((D16-C16)/C16*100%,0) -> 0 | F16: =D16-C16 -> 0
A17: 5 | B17: Maliyyə institutlarına depozitlər və kreditlər (xalis) | C17: ='Daily-Report'!L17 -> 0 | D17: ='Daily-Report'!C17 -> 0 | E17: =IFERROR((D17-C17)/C17*100%,0) -> 0 | F17: =D17-C17 -> 0
A18: 5a | B18: Maliyyə institutlarına depozitlər və kreditlər üzrə məqsədli ehtiyatlar | C18: ='Daily-Report'!L18 -> 0 | D18: ='Daily-Report'!C18 -> 0 | E18: =IFERROR((D18-C18)/C18*100%,0) -> 0 | F18: =D18-C18 -> 0
A19: 6 | B19: Müştərilərə verilən kreditlər və lizinqlər | C19: ='Daily-Report'!L19 -> 0 | D19: ='Daily-Report'!C19 -> 0 | E19: =IFERROR((D19-C19)/C19*100%,0) -> 0 | F19: =D19-C19 -> 0
A20: 6a | B20: Kreditlər üzrə məqsədli ehtiyatlar | C20: ='Daily-Report'!L20 -> 0 | D20: ='Daily-Report'!C20 -> 0 | E20: =IFERROR((D20-C20)/C20*100%,0) -> 0 | F20: =D20-C20 -> 0
A21: 6b | B21: Müştərilərə verilən kreditlər (xalis) | C21: ='Daily-Report'!L21 -> 0 | D21: ='Daily-Report'!C21 -> 0 | E21: =IFERROR((D21-C21)/C21*100%,0) -> 0 | F21: =D21-C21 -> 0
A22: 7 | B22: Amortizasiya çıxılmaqla əsas vəsaitlər (bank işində istifadə olunmayan əsas vəsaitlər daxil olmaqla) | C22: ='Daily-Report'!L22 -> 0 | D22: ='Daily-Report'!C22 -> 0 | E22: =IFERROR((D22-C22)/C22*100%,0) -> 0 | F22: =D22-C22 -> 0
A23: 8 | B23: İnvestisiyalar və maliyyə iştirakı (xalis) | C23: ='Daily-Report'!L23 -> 0 | D23: ='Daily-Report'!C23 -> 0 | E23: =IFERROR((D23-C23)/C23*100%,0) -> 0 | F23: =D23-C23 -> 0
A24: 9 | B24: Digər aktivlər (xalis) | C24: ='Daily-Report'!L24 -> 0 | D24: ='Daily-Report'!C24 -> 0 | E24: =IFERROR((D24-C24)/C24*100%,0) -> 0 | F24: =D24-C24 -> 0
A25: 9a | B25: O cümlədən, hesablanmış alınası faizlər (xalis) | C25: ='Daily-Report'!L25 -> 0 | D25: ='Daily-Report'!C25 -> 0 | E25: =IFERROR((D25-C25)/C25*100%,0) -> 0 | F25: =D25-C25 -> 0
A26: 9b | B26: hesablanmış alınası faizlər üzrə məqsədli ehtiyatlar | C26: ='Daily-Report'!L26 -> 0 | D26: ='Daily-Report'!C26 -> 0 | E26: =IFERROR((D26-C26)/C26*100%,0) -> 0 | F26: =D26-C26 -> 0
B27: Digər məqsədli ehtiyatlar (4a,5a,6a,9b bəndləri istisna olmaqla) | C27: ='Daily-Report'!L27 -> 0 | D27: ='Daily-Report'!C27 -> 0 | E27: =IFERROR((D27-C27)/C27*100%,0) -> 0 | F27: =D27-C27 -> 0
A28: AKTİVLƏR CƏMİ | C28: =C6+C7+C14+C15+C17+C21+C22+C23+C24 -> 0 | D28: =D6+D7+D14+D15+D17+D21+D22+D23+D24 -> 0 | E28: =IFERROR((D28-C28)/C28*100%,0) -> 0 | F28: =D28-C28 -> 0
A29: PASSİVLƏR | C29: CƏMİ | D29: CƏMİ
A30: 10 | B30: Tələbli depozitləri | C30: ='Daily-Report'!L30 -> 0 | D30: ='Daily-Report'!C30 -> 0 | E30: =IFERROR((D30-C30)/C30*100%,0) -> 0 | F30: =D30-C30 -> 0
A31: 10a | B31: Hüquqi şəxslər | C31: ='Daily-Report'!L31 -> 0 | D31: ='Daily-Report'!C31 -> 0 | E31: =IFERROR((D31-C31)/C31*100%,0) -> 0 | F31: =D31-C31 -> 0
A32: 10b | B32: Fiziki şəxslər | C32: ='Daily-Report'!L32 -> 0 | D32: ='Daily-Report'!C32 -> 0 | E32: =IFERROR((D32-C32)/C32*100%,0) -> 0 | F32: =D32-C32 -> 0
A33: 11 | B33: Müddətli depozitləri | C33: ='Daily-Report'!L33 -> 0 | D33: ='Daily-Report'!C33 -> 0 | E33: =IFERROR((D33-C33)/C33*100%,0) -> 0 | F33: =D33-C33 -> 0
A34: 11a | B34: Hüquqi şəxslər | C34: ='Daily-Report'!L34 -> 0 | D34: ='Daily-Report'!C34 -> 0 | E34: =IFERROR((D34-C34)/C34*100%,0) -> 0 | F34: =D34-C34 -> 0
A35: 11b | B35: Fiziki şəxslər | C35: ='Daily-Report'!L35 -> 0 | D35: ='Daily-Report'!C35 -> 0 | E35: =IFERROR((D35-C35)/C35*100%,0) -> 0 | F35: =D35-C35 -> 0
A36: 12 | B36: AMB-nin banka qarşı tələbi | C36: ='Daily-Report'!L36 -> 0 | D36: ='Daily-Report'!C36 -> 0 | E36: =IFERROR((D36-C36)/C36*100%,0) -> 0 | F36: =D36-C36 -> 0
A37: 13 | B37: Bankların tələbləri (Loro) | C37: ='Daily-Report'!L37 -> 0 | D37: ='Daily-Report'!C37 -> 0 | E37: =IFERROR((D37-C37)/C37*100%,0) -> 0 | F37: =D37-C37 -> 0
A38: 14 | B38: Maliyyə sektoru institutlarından cəlb edilən vəsaitlər | C38: ='Daily-Report'!L38 -> 0 | D38: ='Daily-Report'!C38 -> 0 | E38: =IFERROR((D38-C38)/C38*100%,0) -> 0 | F38: =D38-C38 -> 0
A39: 14a | B39: Bankların depozitləri və kreditləri | C39: ='Daily-Report'!L39 -> 0 | D39: ='Daily-Report'!C39 -> 0 | E39: =IFERROR((D39-C39)/C39*100%,0) -> 0 | F39: =D39-C39 -> 0
A40: 14c | B40: Maliyyə institutlarının depozitləri və kreditləri | C40: ='Daily-Report'!L40 -> 0 | D40: ='Daily-Report'!C40 -> 0 | E40: =IFERROR((D40-C40)/C40*100%,0) -> 0 | F40: =D40-C40 -> 0
A41: 15 | B41: Digər öhdəliklər | C41: ='Daily-Report'!L41 -> 0 | D41: ='Daily-Report'!C41 -> 0 | E41: =IFERROR((D41-C41)/C41*100%,0) -> 0 | F41: =D41-C41 -> 0
...

Sheet Sheet2
L1: min manatla
A2: N | B2: Bankın adı | C2: Aktivlərdə xalis dəyişmə | D2: Aktivlərdə xalis dəyişmə,%-lə | E2: Likvid aktivlər/cari öhdəliklər, %-lə | F2: Likvid aktivlər/cəmi aktivlər,%-lə | G2: KP-nin əsas məbləği üzrə məqsədli ehtiyatlarda dəyişmə, %-lə | H2: Gün ərzində fiziki şəxslərin müddətli əmanətlərində xalis dəyişmə,% | I2: Cari ilin mənfəətində (zərərində) dəyişmə | J2: Balans kapitalında xalis dəyişmə,%-lə | K2: Gün ərzində verilmiş kreditlər,cəmi | L2: Gün ərzində verilmiş istehlak kreditləri
A3: 1 | B3: BANKIN ADI | C3: =Daily!F28 -> 0 | D3: =Daily!E28 -> 0 | E3: =Daily!D78 -> 0 | F3: =Daily!D79 -> 0 | G3: =Daily!E20 -> 0 | H3: =Daily!E35 -> 0 | I3: =Daily!E45 -> 0 | J3: =Daily!E44 -> 0 | K3: =Daily!D74 -> #REF! | L3: =Daily!D80 -> 0

Sheet Daily-Report
A1: AKTİV VƏ PASSİVLƏRİN VALYUTA STRUKTURU
A2: Bank Melli İran Bakı filialı
A3: Tarix:31-01-2025 | J3: Tarix :30-01-2025 | S3: =A3 -> Tarix: 22/01/2024 | U3: - | W3: =J3 -> Tarix :30-01-2025
A4: I Hissə – Balans hesabatı - valyuta stukturu (min manatla) | J4: I Hissə – Balans hesabatı - valyuta stukturu (min manatla) | S4: FƏRQ
A5: AKTİVLƏR | C5: CƏMİ | D5: MANAT | E5: USD | F5: EURO | G5: RUBL | H5: DİGƏR | J5: AKTİVLƏR | L5: CƏMİ | M5: MANAT | N5: USD | O5: EURO | P5: RUBL | Q5: DİGƏR | S5: CƏMİ | T5: MANAT | U5: USD | V5: EURO | W5: RUBL | X5: DİGƏR
A6: 1 | B6: Nağd vəsaitlər | C6: =D6+E6+F6+G6+H6 -> 3208.3558 | D6: 396.65163 | E6: 1833.4415 | F6: 978.26269 | G6: 0 | H6: 0 | J6: 1 | K6: Nağd vəsaitlər | L6: =M6+N6+O6+P6+Q6 -> 3209.2666 | M6: 428.57617 | N6: 1822.5173 | O6: 958.17315 | P6: 0 | Q6: 0 | S6: =C6-L6 -> -0.9108 | T6: =D6-M6 -> -31.92454 | U6: =E6-N6 -> 10.9242 | V6: =F6-O6 -> 20.08954 | W6: =G6-P6 -> 0 | X6: =H6-Q6 -> 0 | Y6: bax: səhifə | Z6: 1 Nağd vəsaitlər
A7: 2 | B7: Müxbir hesablar | C7: =C8+C10+C12 -> 35219.23 | D7: =D8+D10+D12 -> 3922.9083 | E7: =E8+E10+E12 -> 948.3841 | F7: =F8+F10+F12 -> 30346.957 | G7: =G8+G10+G12 -> 0.00834 | H7: =H8+H10+H12 -> 0.97208 | J7: 2 | K7: Müxbir hesablar | L7: =L8+L10+L12 -> 35741.38 | M7: =M8+M10+M12 -> 4353.9907 | N7: =N8+N10+N12 -> 948.3841 | O7: =O8+O10+O12 -> 30438.038 | P7: =P8+P10+P12 -> 0.00827 | Q7: =Q8+Q10+Q12 -> 0.95923 | S7: =C7-L7 -> -522.14981 | T7: =D7-M7 -> -431.08234 | U7: =E7-N7 -> 0 | V7: =F7-O7 -> -91.08039 | W7: =G7-P7 -> 7e-05 | X7: =H7-Q7 -> 0.01285
A8: 2a | B8: AMB | C8: =D8+E8+F8+G8+H8 -> 35194.708 | D8: 3922.9083 | E8: 948.3841 | F8: 30323.416 | G8: 0 | H8: 0 | J8: 2a | K8: AMB | L8: =M8+N8+O8+P8+Q8 -> 35716.801 | M8: 4353.9907 | N8: 948.3841 | O8: 30414.426 | P8: 0 | Q8: 0 | S8: =C8-L8 -> -522.09209 | T8: =D8-M8 -> -431.08234 | U8: =E8-N8 -> 0 | V8: =F8-O8 -> -91.00975 | W8: =G8-P8 -> 0 | X8: =H8-Q8 -> 0 | Y8: bax: səhifə | Z8: 2a AMB
A9: 2a.1 | B9: o cümlədən blokda olan vəsaitlər | C9: =D9+E9+F9+G9+H9 -> 0.61156 | D9: 0.61156 | E9: 0 | F9: 0 | J9: 2a.1 | K9: o cümlədən blokda olan vəsaitlər | L9: =M9+N9+O9+P9+Q9 -> 0.61156 | M9: 0.61156 | N9: 0 | O9: 0 | S9: =C9-L9 -> 0 | T9: =D9-M9 -> 0 | U9: =E9-N9 -> 0 | V9: =F9-O9 -> 0 | W9: =G9-P9 -> 0 | X9: =H9-Q9 -> 0
A10: 2b | B10: Rezident banklarda müxbir hesablar (xalis) | C10: =D10+E10+F10+G10+H10 -> 0 | D10: 0 | E10: 0 | F10: 0 | G10: 0 | H10: 0 | J10: 2b | K10: Rezident banklarda müxbir hesablar (xalis) | L10: =M10+N10+O10+P10+Q10 -> 0 | M10: 0 | N10: 0 | O10: 0 | P10: 0 | Q10: 0 | S10: =C10-L10 -> 0 | T10: =D10-M10 -> 0 | U10: =E10-N10 -> 0 | V10: =F10-O10 -> 0 | W10: =G10-P10 -> 0 | X10: =H10-Q10 -> 0 | Y10: bax: səhifə | Z10: 2b Rez. banklarda muxbir
A11: 2b.1 | B11: o cümlədən blokda olan vəsaitlər | C11: =D11+E11+F11+G11+H11 -> 0 | J11: 2b.1 | K11: o cümlədən blokda olan vəsaitlər | L11: =M11+N11+O11+P11+Q11 -> 0 | S11: =C11-L11 -> 0 | T11: =D11-M11 -> 0 | U11: =E11-N11 -> 0 | V11: =F11-O11 -> 0 | W11: =G11-P11 -> 0 | X11: =H11-Q11 -> 0
A12: 2c | B12: Qeyri-rezident banklarda müxbir hesablar (xalis) | C12: =D12+E12+F12+G12+H12 -> 24.52177 | D12: 0 | E12: 0 | F12: 23.54135 | G12: 0.00834 | H12: 0.97208 | J12: 2c | K12: Qeyri-rezident banklarda müxbir hesablar (xalis) | L12: =M12+N12+O12+P12+Q12 -> 24.57949 | M12: 0 | N12: 0 | O12: 23.61199 | P12: 0.00827 | Q12: 0.95923 | S12: =C12-L12 -> -0.05772 | T12: =D12-M12 -> 0 | U12: =E12-N12 -> 0 | V12: =F12-O12 -> -0.07064 | W12: =G12-P12 -> 7e-05 | X12: =H12-Q12 -> 0.01285 | Y12: bax: səhifə | Z12: 2c Qeyri Rez.banklarda muxbir
A13: 2c.1 | B13: o cümlədən blokda olan vəsaitlər | C13: =D13+E13+F13+G13+H13 -> 0 | J13: 2c.1 | K13: o cümlədən blokda olan vəsaitlər | L13: =M13+N13+O13+P13+Q13 -> 0 | S13: =C13-L13 -> 0 | T13: =D13-M13 -> 0 | U13: =E13-N13 -> 0 | V13: =F13-O13 -> 0 | W13: =G13-P13 -> 0 | X13: =H13-Q13 -> 0
A14: 3 | B14: Qiymətli kağızlar (xalis) | C14: =D14+E14+F14+G14+H14 -> 32840.046 | D14: 32840.046 | E14: 0 | F14: 0 | G14: 0 | H14: 0 | J14: 3 | K14: Qiymətli kağızlar (xalis) | L14: =M14+N14+O14+P14+Q14 -> 32840.046 | M14: 32840.046 | N14: 0 | O14: 0 | P14: 0 | Q14: 0 | S14: =C14-L14 -> 0 | T14: =D14-M14 -> 0 | U14: =E14-N14 -> 0 | V14: =F14-O14 -> 0 | W14: =G14-P14 -> 0 | X14: =H14-Q14 -> 0 | Y14: bax: səhifə | Z14: 3 Qiymətli kağızlar
A15: 4 | B15: Banklara depozitlər və kreditlər (xalis) | C15: =D15+E15+F15+G15+H15 -> 0 | D15: 0 | E15: 0 | F15: 0 | G15: 0 | H15: 0 | J15: 4 | K15: Banklara depozitlər və kreditlər (xalis) | L15: =M15+N15+O15+P15+Q15 -> 0 | M15: 0 | N15: 0 | O15: 0 | P15: 0 | Q15: 0 | S15: =C15-L15 -> 0 | T15: =D15-M15 -> 0 | U15: =E15-N15 -> 0 | V15: =F15-O15 -> 0 | W15: =G15-P15 -> 0 | X15: =H15-Q15 -> 0 | Y15: bax: səhifə | Z15: 4 banklara dep ve kreditler
A16: 4a | B16: Banklara depozitlər və kreditlər üzrə məqsədli ehtiyatlar | C16: =D16+E16+F16+G16+H16 -> -5379.799 | D16: -5379.799 | E16: 0 | F16: 0 | G16: 0 | H16: 0 | J16: 4a | K16: Banklara depozitlər və kreditlər üzrə məqsədli ehtiyatlar | L16: =M16+N16+O16+P16+Q16 -> -5379.799 | M16: -5379.799 | N16: 0 | O16: 0 | P16: 0 | Q16: 0 | S16: =C16-L16 -> 0 | T16: =D16-M16 -> 0 | U16: =E16-N16 -> 0 | V16: =F16-O16 -> 0 | W16: =G16-P16 -> 0 | X16: =H16-Q16 -> 0
A17: 5 | B17: Maliyyə institutlarına depozitlər və kreditlər (xalis) | C17: =D17+E17+F17+G17+H17 -> 0 | D17: 0 | E17: 0 | F17: 0 | G17: 0 | H17: 0 | J17: 5 | K17: Maliyyə institutlarına depozitlər və kreditlər (xalis) | L17: =M17+N17+O17+P17+Q17 -> 0 | M17: 0 | N17: 0 | O17: 0 | P17: 0 | Q17: 0 | S17: =C17-L17 -> 0 | T17: =D17-M17 -> 0 | U17: =E17-N17 -> 0 | V17: =F17-O17 -> 0 | W17: =G17-P17 -> 0 | X17: =H17-Q17 -> 0 | Y17: bax: səhifə | Z17: 5 Mal.inst dep ve kreditler
A18: 5a | B18: Maliyyə institutlarına depozitlər və kreditlər üzrə məqsədli ehtiyatlar | C18: =D18+E18+F18+G18+H18 -> 0 | J18: 5a | K18: Maliyyə institutlarına depozitlər və kreditlər üzrə məqsədli ehtiyatlar | L18: =M18+N18+O18+P18+Q18 -> 0 | S18: =C18-L18 -> 0 | T18: =D18-M18 -> 0 | U18: =E18-N18 -> 0 | V18: =F18-O18 -> 0 | W18: =G18-P18 -> 0 | X18: =H18-Q18 -> 0
A19: 6 | B19: Müştərilərə verilən kreditlər və lizinqlər | C19: =D19+E19+F19+G19+H19 -> 3031.9985 | D19: 3031.9985 | E19: 0 | F19: 0 | G19: 0 | H19: 0 | J19: 6 | K19: Müştərilərə verilən kreditlər və lizinqlər | L19: =M19+N19+O19+P19+Q19 -> 3037.6954 | M19: 3037.6954 | N19: 0 | O19: 0 | P19: 0 | Q19: 0 | S19: =C19-L19 -> -5.69695 | T19: =D19-M19 -> -5.69695 | U19: =E19-N19 -> 0 | V19: =F19-O19 -> 0 | W19: =G19-P19 -> 0 | X19: =H19-Q19 -> 0 | Y19: bax: səhifə | Z19: 6.Musterilere verilen kreditler
A20: 6a | B20: Kreditlər üzrə məqsədli ehtiyatlar | C20: =D20+E20+F20+G20+H20 -> -1530.8083 | D20: -1530.8083 | E20: 0 | F20: 0 | G20: 0 | H20: 0 | J20: 6a | K20: Kreditlər üzrə məqsədli ehtiyatlar | L20: =M20+N20+O20+P20+Q20 -> -1534.5025 | M20: -1534.5025 | N20: 0 | O20: 0 | P20: 0 | Q20: 0 | S20: =C20-L20 -> 3.69418 | T20: =D20-M20 -> 3.69418 | U20: =E20-N20 -> 0 | V20: =F20-O20 -> 0 | W20: =G20-P20 -> 0 | X20: =H20-Q20 -> 0
A21: 6b | B21: Müştərilərə verilən kreditlər (xalis) | C21: =D21+E21+F21+G21+H21 -> 1501.1902 | D21: 1501.1902 | E21: 0 | F21: 0 | G21: 0 | H21: 0 | J21: 6b | K21: Müştərilərə verilən kreditlər (xalis) | L21: =M21+N21+O21+P21+Q21 -> 1503.193 | M21: 1503.193 | N21: 0 | O21: 0 | P21: 0 | Q21: 0 | S21: =C21-L21 -> -2.00277 | T21: =D21-M21 -> -2.00277 | U21: =E21-N21 -> 0 | V21: =F21-O21 -> 0 | W21: =G21-P21 -> 0 | X21: =H21-Q21 -> 0
A22: 7 | B22: Amortizasiya çıxılmaqla əsas vəsaitlər (bank işində istifadə olunmayan əsas vəsaitlər daxil olmaqla) | C22: =D22+E22+F22+G22+H22 -> 4877.0067 | D22: 4877.0067 | E22: 0 | F22: 0 | G22: 0 | H22: 0 | J22: 7 | K22: Amortizasiya çıxılmaqla əsas vəsaitlər (bank işində istifadə olunmayan əsas vəsaitlər daxil olmaqla) | L22: =M22+N22+O22+P22+Q22 -> 4877.0067 | M22: 4877.0067 | N22: 0 | O22: 0 | P22: 0 | Q22: 0 | S22: =C22-L22 -> 0 | T22: =D22-M22 -> 0 | U22: =E22-N22 -> 0 | V22: =F22-O22 -> 0 | W22: =G22-P22 -> 0 | X22: =H22-Q22 -> 0
A23: 8 | B23: İnvestisiyalar və maliyyə iştirakı (xalis) | C23: =D23+E23+F23+G23+H23 -> 0 | J23: 8 | K23: İnvestisiyalar və maliyyə iştirakı (xalis) | L23: =M23+N23+O23+P23+Q23 -> 0 | S23: =C23-L23 -> 0 | T23: =D23-M23 -> 0 | U23: =E23-N23 -> 0 | V23: =F23-O23 -> 0 | W23: =G23-P23 -> 0 | X23: =H23-Q23 -> 0
A24: 9 | B24: Digər aktivlər (xalis) | C24: =D24+E24+F24+G24+H24 -> 41875.608 | D24: 41875.608 | E24: 0 | F24: 0 | G24: 0 | H24: 0 | J24: 9 | K24: Digər aktivlər (xalis) | L24: =M24+N24+O24+P24+Q24 -> 41435.774 | M24: 41435.774 | N24: 0 | O24: 0 | P24: 0 | Q24: 0 | S24: =C24-L24 -> 439.83457 | T24: =D24-M24 -> 439.83457 | U24: =E24-N24 -> 0 | V24: =F24-O24 -> 0 | W24: =G24-P24 -> 0 | X24: =H24-Q24 -> 0
A25: 9a | B25: O cümlədən, hesablanmış alınası faizlər (xalis) | C25: =D25+E25+F25+G25+H25 -> 224.21243 | D25: 224.21243 | E25: 0 | F25: 0 | G25: 0 | H25: 0 | J25: 9a | K25: O cümlədən, hesablanmış alınası faizlər (xalis) | L25: =M25+N25+O25+P25+Q25 -> 266.29329 | M25: 266.29329 | N25: 0 | O25: 0 | P25: 0 | Q25: 0 | S25: =C25-L25 -> -42.08086 | T25: =D25-M25 -> -42.08086 | U25: =E25-N25 -> 0 | V25: =F25-O25 -> 0 | W25: =G25-P25 -> 0 | X25: =H25-Q25 -> 0
A26: 9b | B26: hesablanmış alınası faizlər üzrə məqsədli ehtiyatlar | C26: =D26+E26+F26+G26+H26 -> -285.56398 | D26: -285.56398 | E26: 0 | F26: 0 | G26: 0 | H26: 0 | J26: 9b | K26: hesablanmış alınası faizlər üzrə məqsədli ehtiyatlar | L26: =M26+N26+O26+P26+Q26 -> -286.22121 | M26: -286.22121 | N26: 0 | O26: 0 | P26: 0 | Q26: 0 | S26: =C26-L26 -> 0.65723 | T26: =D26-M26 -> 0.65723 | U26: =E26-N26 -> 0 | V26: =F26-O26 -> 0 | W26: =G26-P26 -> 0 | X26: =H26-Q26 -> 0
B27: Digər məqsədli ehtiyatlar (4a,5a,6a,9b bəndləri istisna olmaqla) | C27: =D27+E27+F27+G27+H27 -> -7792.3632 | D27: -7792.3632 | E27: 0 | F27: 0 | G27: 0 | H27: 0 | K27: Digər məqsədli ehtiyatlar (4a,5a,6a,9b bəndləri istisna olmaqla) | L27: =M27+N27+O27+P27+Q27 -> -7792.3632 | M27: -7792.3632 | N27: 0 | O27: 0 | P27: 0 | Q27: 0 | S27: =C27-L27 -> 0 | T27: =D27-M27 -> 0 | U27: =E27-N27 -> 0 | V27: =F27-O27 -> 0 | W27: =G27-P27 -> 0 | X27: =H27-Q27 -> 0
A28: AKTİVLƏR CƏMİ | C28: =C6+C7+C14+C15+C17+C21+C22+C23+C24 -> 119521.44 | D28: =D6+D7+D14+D15+D17+D21+D22+D23+D24 -> 85413.411 | E28: =E6+E7+E14+E15+E17+E21+E22+E23+E24 -> 2781.8256 | F28: =F6+F7+F14+F15+F17+F21+F22+F23+F24 -> 31325.22 | G28: =G6+G7+G14+G15+G17+G21+G22+G23+G24 -> 0.00834 | H28: =H6+H7+H14+H15+H17+H21+H22+H23+H24 -> 0.97208 | J28: AKTİVLƏR CƏMİ | L28: =L6+L7+L14+L15+L17+L21+L22+L23+L24 -> 119606.67 | M28: =M6+M7+M14+M15+M17+M21+M22+M23+M24 -> 85438.586 | N28: =N6+N7+N14+N15+N17+N21+N22+N23+N24 -> 2770.9014 | O28: =O6+O7+O14+O15+O17+O21+O22+O23+O24 -> 31396.211 | P28: =P6+P7+P14+P15+P17+P21+P22+P23+P24 -> 0.00827 | Q28: =Q6+Q7+Q14+Q15+Q17+Q21+Q22+Q23+Q24 -> 0.95923 | S28: =C28-L28 -> -85.22881 | T28: =D28-M28 -> -25.17508 | U28: =E28-N28 -> 10.9242 | V28: =F28-O28 -> -70.99085 | W28: =G28-P28 -> 7e-05 | X28: =H28-Q28 -> 0.01285
A29: PASSİVLƏR | C29: CƏMİ | D29: MANAT | E29: USD | F29: EURO | G29: RUBL | H29: DİGƏR | J29: PASSİVLƏR | L29: CƏMİ | M29: MANAT | N29: USD | O29: EURO | P29: RUBL | Q29: DİGƏR | S29: CƏMİ | T29: MANAT | U29: USD | V29: EURO | W29: RUBL | X29: DİGƏR
A30: 10 | B30: Tələbli depozitləri | C30: =C31+C32 -> 35658.687 | D30: =D31+D32 -> 34761.535 | E30: =E31+E32 -> 641.82868 | F30: =F31+F32 -> 255.32388 | G30: =G31+G32 -> 0 | H30: =H31+H32 -> 0 | J30: 10 | K30: Tələbli depozitləri | L30: =L31+L32 -> 35659.804 | M30: =M31+M32 -> 34761.885 | N30: =N31+N32 -> 641.82868 | O30: =O31+O32 -> 256.09018 | P30: =P31+P32 -> 0 | Q30: =Q31+Q32 -> 0 | S30: =C30-L30 -> -1.11717 | T30: =D30-M30 -> -0.35087 | U30: =E30-N30 -> 0 | V30: =F30-O30 -> -0.7663 | W30: =G30-P30 -> 0 | X30: =H30-Q30 -> 0
A31: 10a | B31: Hüquqi şəxslər | C31: =D31+E31+F31+G31+H31 -> 34967.322 | D31: 34633.238 | E31: 134.0257 | F31: 200.0586 | G31: 0 | H31: 0 | J31: 10a | K31: Hüquqi şəxslər | L31: =M31+N31+O31+P31+Q31 -> 34967.923 | M31: 34633.238 | N31: 134.0257 | O31: 200.65903 | P31: 0 | Q31: 0 | S31: =C31-L31 -> -0.60043 | T31: =D31-M31 -> 0 | U31: =E31-N31 -> 0 | V31: =F31-O31 -> -0.60043 | W31: =G31-P31 -> 0 | X31: =H31-Q31 -> 0 | Y31: bax: səhifə | Z31: 10 telebli ve 11muddetli dep+
A32: 10b | B32: Fiziki şəxslər | C32: =D32+E32+F32+G32+H32 -> 691.36467 | D32: 128.29641 | E32: 507.80298 | F32: 55.26528 | G32: 0 | H32: 0 | J32: 10b | K32: Fiziki şəxslər | L32: =M32+N32+O32+P32+Q32 -> 691.88141 | M32: 128.64728 | N32: 507.80298 | O32: 55.43115 | P32: 0 | Q32: 0 | S32: =C32-L32 -> -0.51674 | T32: =D32-M32 -> -0.35087 | U32: =E32-N32 -> 0 | V32: =F32-O32 -> -0.16587 | W32: =G32-P32 -> 0 | X32: =H32-Q32 -> 0 | Y32: bax: səhifə | Z32: 10 telebli ve 11muddetli dep+
A33: 11 | B33: Müddətli depozitləri | C33: =D33+E33+F33+G33+H33 -> 0 | D33: =D34+D35 -> 0 | E33: =E34+E35 -> 0 | F33: =F34+F35 -> 0 | G33: =G34+G35 -> 0 | H33: =H34+H35 -> 0 | J33: 11 | K33: Müddətli depozitləri | L33: =M33+N33+O33+P33+Q33 -> 0 | M33: =M34+M35 -> 0 | N33: =N34+N35 -> 0 | O33: =O34+O35 -> 0 | P33: =P34+P35 -> 0 | Q33: =Q34+Q35 -> 0 | S33: =C33-L33 -> 0 | T33: =D33-M33 -> 0 | U33: =E33-N33 -> 0 | V33: =F33-O33 -> 0 | W33: =G33-P33 -> 0 | X33: =H33-Q33 -> 0
A34: 11a | B34: Hüquqi şəxslər | C34: =D34+E34+F34+G34+H34 -> 0 | J34: 11a | K34: Hüquqi şəxslər | L34: =M34+N34+O34+P34+Q34 -> 0 | S34: =C34-L34 -> 0 | T34: =D34-M34 -> 0 | U34: =E34-N34 -> 0 | V34: =F34-O34 -> 0 | W34: =G34-P34 -> 0 | X34: =H34-Q34 -> 0 | Y34: bax: səhifə | Z34: 10 telebli ve 11muddetli dep+
A35: 11b | B35: Fiziki şəxslər | C35: =D35+E35+F35+G35+H35 -> 0 | D35: 0 | E35: 0 | F35: 0 | G35: 0 | H35: 0 | J35: 11b | K35: Fiziki şəxslər | L35: =M35+N35+O35+P35+Q35 -> 0 | M35: 0 | N35: 0 | O35: 0 | P35: 0 | Q35: 0 | S35: =C35-L35 -> 0 | T35: =D35-M35 -> 0 | U35: =E35-N35 -> 0 | V35: =F35-O35 -> 0 | W35: =G35-P35 -> 0 | X35: =H35-Q35 -> 0 | Y35: bax: səhifə | Z35: 10 telebli ve 11muddetli dep+
A36: 12 | B36: AMB-nin banka qarşı tələbi | C36: =D36+E36+F36+G36+H36 -> 0 | D36: 0 | E36: 0 | F36: 0 | G36: 0 | H36: 0 | J36: 12 | K36: AMB-nin banka qarşı tələbi | L36: =M36+N36+O36+P36+Q36 -> 0 | M36: 0 | N36: 0 | O36: 0 | P36: 0 | Q36: 0 | S36: =C36-L36 -> 0 | T36: =D36-M36 -> 0 | U36: =E36-N36 -> 0 | V36: =F36-O36 -> 0 | W36: =G36-P36 -> 0 | X36: =H36-Q36 -> 0
A37: 13 | B37: Bankların tələbləri (Loro) | C37: =D37+E37+F37+G37+H37 -> 16439.806 | D37: 0 | E37: 2997.2193 | F37: 13442.587 | G37: 0 | H37: 0 | J37: 13 | K37: Bankların tələbləri (Loro) | L37: =M37+N37+O37+P37+Q37 -> 16480.151 | M37: 0 | N37: 2997.2193 | O37: 13482.932 | P37: 0 | Q37: 0 | S37: =C37-L37 -> -40.34526 | T37: =D37-M37 -> 0 | U37: =E37-N37 -> 0 | V37: =F37-O37 -> -40.34526 | W37: =G37-P37 -> 0 | X37: =H37-Q37 -> 0 | Y37: bax: səhifə | Z37: 13 banklarin telebleri loro
A38: 14 | B38: Maliyyə sektoru institutlarından cəlb edilən vəsaitlər | C38: =D38+E38+F38+G38+H38 -> 15893.1 | D38: =D39+D40 -> 0 | E38: =E39+E40 -> 0 | F38: =F39+F40 -> 15893.1 | G38: =G39+G40 -> 0 | H38: =H39+H40 -> 0 | J38: 14 | K38: Maliyyə sektoru institutlarından cəlb edilən vəsaitlər | L38: =M38+N38+O38+P38+Q38 -> 15940.8 | M38: =M39+M40 -> 0 | N38: =N39+N40 -> 0 | O38: =O39+O40 -> 15940.8 | P38: =P39+P40 -> 0 | Q38: =Q39+Q40 -> 0 | S38: =C38-L38 -> -47.7 | T38: =D38-M38 -> 0 | U38: =E38-N38 -> 0 | V38: =F38-O38 -> -47.7 | W38: =G38-P38 -> 0 | X38: =H38-Q38 -> 0
A39: 14a | B39: Bankların depozitləri və kreditləri | C39: =D39+E39+F39+G39+H39 -> 15893.1 | D39: 0 | E39: 0 | F39: 15893.1 | G39: 0 | H39: 0 | J39: 14a | K39: Bankların depozitləri və kreditləri | L39: =M39+N39+O39+P39+Q39 -> 15940.8 | M39: 0 | N39: 0 | O39: 15940.8 | P39: 0 | Q39: 0 | S39: =C39-L39 -> -47.7 | T39: =D39-M39 -> 0 | U39: =E39-N39 -> 0 | V39: =F39-O39 -> -47.7 | W39: =G39-P39 -> 0 | X39: =H39-Q39 -> 0
A40: 14c | B40: Maliyyə institutlarının depozitləri və kreditləri | C40: =D40+E40+F40+G40+H40 -> 0 | J40: 14c | K40: Maliyyə institutlarının depozitləri və kreditləri | L40: =M40+N40+O40+P40+Q40 -> 0 | S40: =C40-L40 -> 0 | T40: =D40-M40 -> 0 | U40: =E40-N40 -> 0 | V40: =F40-O40 -> 0 | W40: =G40-P40 -> 0 | X40: =H40-Q40 -> 0 | Y40: bax: səhifə | Z40: 14 mal.inst celb edilen vesait+
...

Sheet 1
A1: ='Daily-Report'!A3 -> Tarix: 22/01/2024 | J1: Açıqlamalar aşağıdakı kimidir
A2: AKTİVLƏR | C2: CƏMİ | D2: MANAT | E2: USD | F2: EURO | G2: RUBL | H2: DİGƏR
A3: 1 | B3: Nağd vəsaitlər | C3: =D3+E3+F3+G3+H3 -> 0 | D3: ='Daily-Report'!D6 -> 0 | E3: ='Daily-Report'!E6 -> 0 | F3: ='Daily-Report'!F6 -> 0 | G3: ='Daily-Report'!G6 -> 0 | H3: ='Daily-Report'!H6 -> 0 | J3: Musteri adi | K3: Valyutasi | L3: min AZN ekvivalentinde
A4: ='Daily-Report'!J3 -> Tarix 19/01/2024
A5: AKTİVLƏR | C5: CƏMİ | D5: MANAT | E5: USD | F5: EURO | G5: RUBL | H5: DİGƏR
A6: 1 | B6: Nağd vəsaitlər | C6: =D6+E6+F6+G6+H6 -> 0 | D6: ='Daily-Report'!M6 -> 0 | E6: ='Daily-Report'!N6 -> 0 | F6: ='Daily-Report'!O6 -> 0 | G6: ='Daily-Report'!P6 -> 0 | H6: ='Daily-Report'!Q6 -> 0
A8: FERQ
A9: AKTİVLƏR | C9: CƏMİ | D9: MANAT | E9: USD | F9: EURO | G9: RUBL | H9: DİGƏR
A10: 1 | B10: Nağd vəsaitlər | C10: =D10+E10+F10+G10+H10 -> 0 | D10: =D3-D6 -> 0 | E10: =E3-E6 -> 0 | F10: =F3-F6 -> 0 | G10: =G3-G6 -> 0 | H10: =H3-H6 -> 0
J17: Diger emeliyyatlar (<100k)
J20: Xalis artma (azalma) - AZN equal. | L20: =SUM(L4:L19) -> 0

Sheet 2a
A1: ='Daily-Report'!A3 -> Tarix: 22/01/2024 | J1: Açıqlamalar aşağıdakı kimidir
A2: AKTİVLƏR | C2: CƏMİ | D2: MANAT | E2: USD | F2: EURO | G2: RUBL | H2: DİGƏR
A3: 2a | B3: AMB | C3: =D3+E3+F3+G3+H3 -> 0 | D3: ='Daily-Report'!D8 -> 0 | E3: ='Daily-Report'!E8 -> 0 | F3: ='Daily-Report'!F8 -> 0 | G3: ='Daily-Report'!G8 -> 0 | H3: ='Daily-Report'!H8 -> 0 | J3: Musteri adi | K3: Valyutasi | L3: min AZN ekvivalentinde
A4: ='Daily-Report'!J3 -> Tarix 19/01/2024
A5: AKTİVLƏR | C5: CƏMİ | D5: MANAT | E5: USD | F5: EURO | G5: RUBL | H5: DİGƏR
A6: 2a | B6: AMB | C6: =D6+E6+F6+G6+H6 -> 0 | D6: ='Daily-Report'!M8 -> 0 | E6: ='Daily-Report'!N8 -> 0 | F6: ='Daily-Report'!O8 -> 0 | G6: ='Daily-Report'!P8 -> 0 | H6: ='Daily-Report'!Q8 -> 0
A8: FERQ
A9: AKTİVLƏR | C9: CƏMİ | D9: MANAT | E9: USD | F9: EURO | G9: RUBL | H9: DİGƏR
A10: 2a | B10: AMB | C10: =D10+E10+F10+G10+H10 -> 0 | D10: =D3-D6 -> 0 | E10: =E3-E6 -> 0 | F10: =F3-F6 -> 0 | G10: =G3-G6 -> 0 | H10: =H3-H6 -> 0
J23: Diger emeliyyatlar (<150k)
J28: Xalis artma (azalma) - AZN equal. | L28: =SUM(L4:L27) -> 0

Sheet 2b
A1: ='Daily-Report'!A3 -> Tarix: 22/01/2024 | J1: Açıqlamalar aşağıdakı kimidir
A2: AKTİVLƏR | C2: CƏMİ | D2: MANAT | E2: USD | F2: EURO | G2: RUBL | H2: DİGƏR
A3: 2b | B3: Rezident banklarda müxbir hesablar (xalis) | C3: =D3+E3+F3+G3+H3 -> 0 | D3: ='Daily-Report'!D10 -> 0 | E3: ='Daily-Report'!E10 -> 0 | F3: ='Daily-Report'!F10 -> 0 | G3: ='Daily-Report'!G10 -> 0 | H3: ='Daily-Report'!H10 -> 0 | J3: Musteri adi | K3: Valyutasi | L3: min AZN ekvivalentinde
A4: ='Daily-Report'!J3 -> Tarix 19/01/2024
A5: AKTİVLƏR | C5: CƏMİ | D5: MANAT | E5: USD | F5: EURO | G5: RUBL | H5: DİGƏR
A6: 2b | B6: Rezident banklarda müxbir hesablar (xalis) | C6: =D6+E6+F6+G6+H6 -> 0 | D6: ='Daily-Report'!M10 -> 0 | E6: ='Daily-Report'!N10 -> 0 | F6: ='Daily-Report'!O10 -> 0 | G6: ='Daily-Report'!P10 -> 0 | H6: ='Daily-Report'!Q10 -> 0
A8: FERQ
A9: AKTİVLƏR | C9: CƏMİ | D9: MANAT | E9: USD | F9: EURO | G9: RUBL | H9: DİGƏR
A10: 2b | B10: Rezident banklarda müxbir hesablar (xalis) | C10: =D10+E10+F10+G10+H10 -> 0 | D10: =D3-D6 -> 0 | E10: =E3-E6 -> 0 | F10: =F3-F6 -> 0 | G10: =G3-G6 -> 0 | H10: =H3-H6 -> 0
J15: Xalis artma (azalma) - AZN equal. | L15: =SUM(L4:L13) -> 0

Sheet 2c
A1: ='Daily-Report'!A3 -> Tarix: 22/01/2024 | J1: Açıqlamalar aşağıdakı kimidir
A2: AKTİVLƏR | C2: CƏMİ | D2: MANAT | E2: USD | F2: EURO | G2: RUBL | H2: DİGƏR
A3: 2c | B3: Qeyri-rezident banklarda müxbir hesablar (xalis) | C3: =D3+E3+F3+G3+H3 -> 0 | D3: ='Daily-Report'!D12 -> 0 | E3: ='Daily-Report'!E12 -> 0 | F3: ='Daily-Report'!F12 -> 0 | G3: ='Daily-Report'!G12 -> 0 | H3: ='Daily-Report'!H12 -> 0 | J3: Musteri adi | K3: Valyutasi | L3: min AZN ekvivalentinde
A5: AKTİVLƏR | C5: CƏMİ | D5: MANAT | E5: USD | F5: EURO | G5: RUBL | H5: DİGƏR
A6: 2c | B6: Qeyri-rezident banklarda müxbir hesablar (xalis) | C6: =D6+E6+F6+G6+H6 -> 0 | D6: ='Daily-Report'!M12 -> 0 | E6: ='Daily-Report'!N12 -> 0 | F6: ='Daily-Report'!O12 -> 0 | G6: ='Daily-Report'!P12 -> 0 | H6: ='Daily-Report'!Q12 -> 0
A8: FERQ
A9: AKTİVLƏR | C9: CƏMİ | D9: MANAT | E9: USD | F9: EURO | G9: RUBL | H9: DİGƏR
A10: 2c | B10: Qeyri-rezident banklarda müxbir hesablar (xalis) | C10: =D10+E10+F10+G10+H10 -> 0 | D10: =D3-D6 -> 0 | E10: =E3-E6 -> 0 | F10: =F3-F6 -> 0 | G10: =G3-G6 -> 0 | H10: =H3-H6 -> 0
J26: Diger emeliyyatlar (<100k)
J34: Xalis artma (azalma) - AZN equal. | L34: =SUM(L4:L33) -> 0

Sheet 5 Mal.inst dep ve kreditler

Sheet 3
A1: ='Daily-Report'!A3 -> Tarix: 22/01/2024 | J1: Açıqlamalar aşağıdakı kimidir
A2: AKTİVLƏR | C2: CƏMİ | D2: MANAT | E2: USD | F2: EURO | G2: RUBL | H2: DİGƏR
A3: 3 | B3: Qiymətli kağızlar (xalis) | C3: =D3+E3+F3+G3+H3 -> 0 | D3: ='Daily-Report'!D14 -> 0 | E3: ='Daily-Report'!E14 -> 0 | F3: ='Daily-Report'!F14 -> 0 | G3: ='Daily-Report'!G14 -> 0 | H3: ='Daily-Report'!H14 -> 0 | J3: Musteri adi | K3: Valyutasi | L3: min AZN ekvivalentinde
A4: ='Daily-Report'!J3 -> Tarix 19/01/2024
A5: AKTİVLƏR | C5: CƏMİ | D5: MANAT | E5: USD | F5: EURO | G5: RUBL | H5: DİGƏR
A6: 3 | B6: Qiymətli kağızlar (xalis) | C6: =D6+E6+F6+G6+H6 -> 0 | D6: ='Daily-Report'!M14 -> 0 | E6: ='Daily-Report'!N14 -> 0 | F6: ='Daily-Report'!O14 -> 0 | G6: ='Daily-Report'!P14 -> 0 | H6: ='Daily-Report'!Q14 -> 0
A8: FERQ | J8: Xalis artma (azalma) - AZN equal. | L8: =SUM(L5:L7) -> 0
A9: AKTİVLƏR | C9: CƏMİ | D9: MANAT | E9: USD | F9: EURO | G9: RUBL | H9: DİGƏR
A10: 3 | B10: Qiymətli kağızlar (xalis) | C10: =D10+E10+F10+G10+H10 -> 0 | D10: =D3-D6 -> 0 | E10: =E3-E6 -> 0 | F10: =F3-F6 -> 0 | G10: =G3-G6 -> 0 | H10: =H3-H6 -> 0

Sheet 4
A1: ='Daily-Report'!A3 -> Tarix: 22/01/2024 | J1: Açıqlamalar aşağıdakı kimidir
A2: AKTİVLƏR | C2: CƏMİ | D2: MANAT | E2: USD | F2: EURO | G2: RUBL | H2: DİGƏR
A3: 4 | B3: Banklara depozitlər və kreditlər (xalis) | C3: =D3+E3+F3+G3+H3 -> 0 | D3: ='Daily-Report'!D15 -> 0 | E3: ='Daily-Report'!E15 -> 0 | F3: ='Daily-Report'!F15 -> 0 | G3: ='Daily-Report'!G15 -> 0 | H3: ='Daily-Report'!H15 -> 0 | J3: Musteri adi | K3: Valyutasi | L3: min AZN ekvivalentinde
A4: ='Daily-Report'!J3 -> Tarix 19/01/2024
A5: AKTİVLƏR | C5: CƏMİ | D5: MANAT | E5: USD | F5: EURO | G5: RUBL | H5: DİGƏR
A6: 4 | B6: Banklara depozitlər və kreditlər (xalis) | C6: =D6+E6+F6+G6+H6 -> 0 | D6: ='Daily-Report'!M15 -> 0 | E6: ='Daily-Report'!N15 -> 0 | F6: ='Daily-Report'!O15 -> 0 | G6: ='Daily-Report'!P15 -> 0 | H6: ='Daily-Report'!Q15 -> 0
J7: Xalis artma (azalma) - AZN equal. | L7: =SUM(L4:L6) -> 0
A8: FERQ
A9: AKTİVLƏR | C9: CƏMİ | D9: MANAT | E9: USD | F9: EURO | G9: RUBL | H9: DİGƏR
A10: 4 | B10: Banklara depozitlər və kreditlər (xalis) | C10: =D10+E10+F10+G10+H10 -> 0 | D10: =D3-D6 -> 0 | E10: =E3-E6 -> 0 | F10: =F3-F6 -> 0 | G10: =G3-G6 -> 0 | H10: =H3-H6 -> 0

Sheet 3.Akkreditivlər
A1: ='Daily-Report'!A3 -> Tarix: 22/01/2024 | J1: Açıqlamalar aşağıdakı kimidir
A2: AKTİVLƏR | C2: CƏMİ | D2: MANAT | E2: USD | F2: EURO | G2: RUBL | H2: DİGƏR
A3: 3 | B3: Akkreditivlər | C3: =D3+E3+F3+G3+H3 -> 0 | D3: ='Daily-Report'!D52 -> 0 | E3: ='Daily-Report'!E52 -> 0 | F3: ='Daily-Report'!F52 -> 0 | G3: ='Daily-Report'!G52 -> 0 | H3: ='Daily-Report'!H52 -> 0 | J3: Musteri adi | K3: Valyutasi | L3: min AZN ekvivalentinde
A4: ='Daily-Report'!J3 -> Tarix 19/01/2024
A5: AKTİVLƏR | C5: CƏMİ | D5: MANAT | E5: USD | F5: EURO | G5: RUBL | H5: DİGƏR
A6: 3 | B6: Akkreditivlər | C6: =D6+E6+F6+G6+H6 -> 0 | D6: ='Daily-Report'!M52 -> 0 | E6: ='Daily-Report'!N52 -> 0 | F6: ='Daily-Report'!O52 -> 0 | G6: ='Daily-Report'!P52 -> 0 | H6: ='Daily-Report'!Q52 -> 0
A8: FERQ | J8: Xalis artma (azalma) - AZN equal. | L8: =SUM(L4:L6) -> 0
A9: AKTİVLƏR | C9: CƏMİ | D9: MANAT | E9: USD | F9: EURO | G9: RUBL | H9: DİGƏR
A10: 3 | B10: Akkreditivlər | C10: =D10+E10+F10+G10+H10 -> 0 | D10: =D3-D6 -> 0 | E10: =E3-E6 -> 0 | F10: =F3-F6 -> 0 | G10: =G3-G6 -> 0 | H10: =H3-H6 -> 0

Sheet 7.Digər balansarxası öhdəliklər
A1: ='Daily-Report'!A3 -> Tarix: 22/01/2024 | J1: Açıqlamalar aşağıdakı kimidir
A2: AKTİVLƏR | C2: CƏMİ | D2: MANAT | E2: USD | F2: EURO | G2: RUBL | H2: DİGƏR
A3: 7 | B3: Digər balansarxası öhdəliklər | C3: =D3+E3+F3+G3+H3 -> 0 | D3: ='Daily-Report'!D56 -> 0 | E3: ='Daily-Report'!E56 -> 0 | F3: ='Daily-Report'!F56 -> 0 | G3: ='Daily-Report'!G56 -> 0 | H3: ='Daily-Report'!H56 -> 0 | J3: Musteri adi | K3: Valyutasi | L3: min AZN ekvivalentinde
A4: ='Daily-Report'!J3 -> Tarix 19/01/2024
A5: AKTİVLƏR | C5: CƏMİ | D5: MANAT | E5: USD | F5: EURO | G5: RUBL | H5: DİGƏR
A6: 7 | B6: Digər balansarxası öhdəliklər | C6: =D6+E6+F6+G6+H6 -> 0 | D6: ='Daily-Report'!M56 -> 0 | E6: ='Daily-Report'!N56 -> 0 | F6: ='Daily-Report'!O56 -> 0 | G6: ='Daily-Report'!P56 -> 0 | H6: ='Daily-Report'!Q56 -> 0
A8: FERQ
A9: AKTİVLƏR | C9: CƏMİ | D9: MANAT | E9: USD | F9: EURO | G9: RUBL | H9: DİGƏR
A10: 7 | B10: Digər balansarxası öhdəliklər | C10: =D10+E10+F10+G10+H10 -> 0 | D10: =D3-D6 -> 0 | E10: =E3-E6 -> 0 | F10: =F3-F6 -> 0 | G10: =G3-G6 -> 0 | H10: =H3-H6 -> 0
J11: Xalis artma (azalma) - AZN equal. | L11: =SUM(L4:L9) -> 0

Sheet 5
A1: ='Daily-Report'!A3 -> Tarix: 22/01/2024 | J1: Açıqlamalar aşağıdakı kimidir
A2: AKTİVLƏR | C2: CƏMİ | D2: MANAT | E2: USD | F2: EURO | G2: RUBL | H2: DİGƏR
A3: 4 | B3: Maliyyə institutlarına depozitlər və kreditlər (xalis) | C3: =D3+E3+F3+G3+H3 -> 0 | D3: ='Daily-Report'!D17 -> 0 | E3: ='Daily-Report'!E17 -> 0 | F3: ='Daily-Report'!F17 -> 0 | G3: ='Daily-Report'!G17 -> 0 | H3: ='Daily-Report'!H17 -> 0 | J3: Musteri adi | K3: Valyutasi | L3: min AZN ekvivalentinde
A4: ='Daily-Report'!J3 -> Tarix 19/01/2024
A5: AKTİVLƏR | C5: CƏMİ | D5: MANAT | E5: USD | F5: EURO | G5: RUBL | H5: DİGƏR
A6: 4 | B6: Maliyyə institutlarına depozitlər və kreditlər (xalis) | C6: =D6+E6+F6+G6+H6 -> 0 | D6: ='Daily-Report'!M17 -> 0 | E6: ='Daily-Report'!N17 -> 0 | F6: ='Daily-Report'!O17 -> 0 | G6: ='Daily-Report'!P17 -> 0 | H6: ='Daily-Report'!Q17 -> 0
J7: Xalis artma (azalma) - AZN equal. | L7: =SUM(L4:L6) -> 0
A8: FERQ
A9: AKTİVLƏR | C9: CƏMİ | D9: MANAT | E9: USD | F9: EURO | G9: RUBL | H9: DİGƏR
A10: 4 | B10: Maliyyə institutlarına depozitlər və kreditlər (xalis) | C10: =D10+E10+F10+G10+H10 -> 0 | D10: =D3-D6 -> 0 | E10: =E3-E6 -> 0 | F10: =F3-F6 -> 0 | G10: =G3-G6 -> 0 | H10: =H3-H6 -> 0

Sheet 6
A1: ='Daily-Report'!A3 -> Tarix: 22/01/2024 | J1: Açıqlamalar aşağıdakı kimidir
A2: AKTİVLƏR | C2: CƏMİ | D2: MANAT | E2: USD | F2: EURO | G2: RUBL | H2: DİGƏR
A3: 6 | B3: Müştərilərə verilən kreditlər və lizinqlər | C3: =D3+E3+F3+G3+H3 -> 0 | D3: ='Daily-Report'!D19 -> 0 | E3: ='Daily-Report'!E19 -> 0 | F3: ='Daily-Report'!F19 -> 0 | G3: ='Daily-Report'!G19 -> 0 | H3: ='Daily-Report'!H19 -> 0 | J3: Musteri adi | K3: Valyutasi | L3: min AZN ekvivalentinde
A4: ='Daily-Report'!J3 -> Tarix 19/01/2024
A5: AKTİVLƏR | C5: CƏMİ | D5: MANAT | E5: USD | F5: EURO | G5: RUBL | H5: DİGƏR
A6: 6 | B6: Müştərilərə verilən kreditlər və lizinqlər | C6: =D6+E6+F6+G6+H6 -> 0 | D6: ='Daily-Report'!M19 -> 0 | E6: ='Daily-Report'!N19 -> 0 | F6: ='Daily-Report'!O19 -> 0 | G6: ='Daily-Report'!P19 -> 0 | H6: ='Daily-Report'!Q19 -> 0
A8: FERQ
A9: AKTİVLƏR | C9: CƏMİ | D9: MANAT | E9: USD | F9: EURO | G9: RUBL | H9: DİGƏR
A10: 6 | B10: Müştərilərə verilən kreditlər və lizinqlər | C10: =D10+E10+F10+G10+H10 -> 0 | D10: =D3-D6 -> 0 | E10: =E3-E6 -> 0 | F10: =F3-F6 -> 0 | G10: =G3-G6 -> 0 | H10: =H3-H6 -> 0
J13: Diger emeliyyatlar (<100k) | K13: AZN
J15: Xalis artma (azalma) - AZN equal. | L15: =SUM($L$4:L14) -> 0

Sheet 6a
A1: ='Daily-Report'!A3 -> Tarix: 22/01/2024 | J1: Açıqlamalar aşağıdakı kimidir
A2: AKTİVLƏR | C2: CƏMİ | D2: MANAT | E2: USD | F2: EURO | G2: RUBL | H2: DİGƏR
A3: 6 | B3: Kreditlər üzrə məqsədli ehtiyatlar | C3: =D3+E3+F3+G3+H3 -> 0 | D3: ='Daily-Report'!D20 -> 0 | E3: ='Daily-Report'!E20 -> 0 | F3: ='Daily-Report'!F20 -> 0 | G3: ='Daily-Report'!G20 -> 0 | H3: ='Daily-Report'!H20 -> 0 | J3: Musteri adi | K3: ehtiyatın % dərəcəsi | L3: Valyutasi | M3: min AZN ekvivalentinde
A4: ='Daily-Report'!J3 -> Tarix 19/01/2024 | XFD4: 0.01
A5: AKTİVLƏR | C5: CƏMİ | D5: MANAT | E5: USD | F5: EURO | G5: RUBL | H5: DİGƏR | XFD5: 0.02
A6: 6 | B6: Kreditlər üzrə məqsədli ehtiyatlar | C6: =D6+E6+F6+G6+H6 -> 0 | D6: ='Daily-Report'!M20 -> 0 | E6: ='Daily-Report'!N20 -> 0 | F6: ='Daily-Report'!O20 -> 0 | G6: ='Daily-Report'!P20 -> 0 | H6: ='Daily-Report'!Q20 -> 0 | XFD6: 0.03
XFD7: 0.05
A8: FERQ | XFD8: 0.1
A9: AKTİVLƏR | C9: CƏMİ | D9: MANAT | E9: USD | F9: EURO | G9: RUBL | H9: DİGƏR | XFD9: 0.25
A10: 6 | B10: Kreditlər üzrə məqsədli ehtiyatlar | C10: =D10+E10+F10+G10+H10 -> 0 | D10: =D3-D6 -> 0 | E10: =E3-E6 -> 0 | F10: =F3-F6 -> 0 | G10: =G3-G6 -> 0 | H10: =H3-H6 -> 0 | J10: Diger emeliyyatlar (<100k) | L10: AZN | XFD10: 0.5
J11: Xalis artma (azalma) - AZN equal. | M11: =SUM($M$4:M10) -> 0 | XFD11: 1

Sheet 2
A1: ='Daily-Report'!A3 -> Tarix: 22/01/2024 | J1: Açıqlamalar aşağıdakı kimidir
A2: AKTİVLƏR | C2: CƏMİ | D2: MANAT | E2: USD | F2: EURO | G2: RUBL | H2: DİGƏR
A3: 2 | B3: Balansdankənar hesabat | C3: =D3+E3+F3+G3+H3 -> 0 | D3: ='Daily-Report'!D57 -> 0 | E3: ='Daily-Report'!E57 -> 0 | F3: ='Daily-Report'!F57 -> 0 | G3: ='Daily-Report'!G57 -> 0 | H3: ='Daily-Report'!H57 -> 0 | J3: Musteri adi | K3: Balansdankənar | L3: Valyutasi | M3: min AZN ekvivalentinde
A4: ='Daily-Report'!J3 -> Tarix 19/01/2024
A5: AKTİVLƏR | C5: CƏMİ | D5: MANAT | E5: USD | F5: EURO | G5: RUBL | H5: DİGƏR
A6: 2 | B6: Balansdankənar hesabat | C6: =D6+E6+F6+G6+H6 -> 0 | D6: ='Daily-Report'!M57 -> 0 | E6: ='Daily-Report'!N57 -> 0 | F6: ='Daily-Report'!O57 -> 0 | G6: ='Daily-Report'!P57 -> 0 | H6: ='Daily-Report'!Q57 -> 0
A8: FERQ
A9: AKTİVLƏR | C9: CƏMİ | D9: MANAT | E9: USD | F9: EURO | G9: RUBL | H9: DİGƏR
A10: 2 | B10: Balansdankənar hesabat | C10: =D10+E10+F10+G10+H10 -> 0 | D10: =D3-D6 -> 0 | E10: =E3-E6 -> 0 | F10: =F3-F6 -> 0 | G10: =G3-G6 -> 0 | H10: =H3-H6 -> 0
J16: Xalis artma (azalma) - AZN equal. | M16: =SUM(M4:M15) -> 0

Sheet 10+11
A1: ='Daily-Report'!A3 -> Tarix: 22/01/2024 | J1: Telebli Dep+ | T1: Muddetli Dep+
A2: PASSIVLƏR | C2: CƏMİ | D2: MANAT | E2: USD | F2: EURO | G2: RUBL | H2: DİGƏR | J2: 10a Hüquqi şəxslər | K2: musteri no: | L2: valyuta | M2: min AZN ekv. | O2: 10b Fiziki şəxslər | P2: musteri no: | Q2: valyuta | R2: min AZN ekv. | T2: 11a Hüquqi şəxslər | U2: musteri no: | V2: valyuta | W2: min AZN ekv. | Y2: 11b Fiziki şəxslər | Z2: musteri no: | AA2: valyuta | AB2: min AZN ekv.
A3: 10a | B3: Hüquqi şəxslər | C3: =D3+E3+F3+G3+H3 -> 0 | D3: ='Daily-Report'!D31 -> 0 | E3: ='Daily-Report'!E31 -> 0 | F3: ='Daily-Report'!F31 -> 0 | G3: ='Daily-Report'!G31 -> 0 | H3: ='Daily-Report'!H31 -> 0
A4: 10b | B4: Fiziki şəxslər | C4: =D4+E4+F4+G4+H4 -> 0 | D4: ='Daily-Report'!D32 -> 0 | E4: ='Daily-Report'!E32 -> 0 | F4: ='Daily-Report'!F32 -> 0 | G4: ='Daily-Report'!G32 -> 0 | H4: ='Daily-Report'!H32 -> 0
A5: 11a | B5: Hüquqi şəxslər | C5: =D5+E5+F5+G5+H5 -> 0 | D5: ='Daily-Report'!D34 -> 0 | E5: ='Daily-Report'!E34 -> 0 | F5: ='Daily-Report'!F34 -> 0 | G5: ='Daily-Report'!G34 -> 0 | H5: ='Daily-Report'!H34 -> 0
A6: 11b | B6: Fiziki şəxslər | C6: =D6+E6+F6+G6+H6 -> 0 | D6: ='Daily-Report'!D35 -> 0 | E6: ='Daily-Report'!E35 -> 0 | F6: ='Daily-Report'!F35 -> 0 | G6: ='Daily-Report'!G35 -> 0 | H6: ='Daily-Report'!H35 -> 0
A7: ='Daily-Report'!J3 -> Tarix 19/01/2024 | O7: Diger emeliyyatlar (<150k)
A8: PASSIVLƏR | C8: CƏMİ | D8: MANAT | E8: USD | F8: EURO | G8: RUBL | H8: DİGƏR
A9: 10a | B9: Hüquqi şəxslər | C9: =D9+E9+F9+G9+H9 -> 0 | D9: ='Daily-Report'!M31 -> 0 | E9: ='Daily-Report'!N31 -> 0 | F9: ='Daily-Report'!O31 -> 0 | G9: ='Daily-Report'!P31 -> 0 | H9: ='Daily-Report'!Q31 -> 0
A10: 10b | B10: Fiziki şəxslər | C10: =D10+E10+F10+G10+H10 -> 0 | D10: ='Daily-Report'!M32 -> 0 | E10: ='Daily-Report'!N32 -> 0 | F10: ='Daily-Report'!O32 -> 0 | G10: ='Daily-Report'!P32 -> 0 | H10: ='Daily-Report'!Q32 -> 0
A11: 11a | B11: Hüquqi şəxslər | C11: =D11+E11+F11+G11+H11 -> 0 | D11: ='Daily-Report'!M34 -> 0 | E11: ='Daily-Report'!N34 -> 0 | F11: ='Daily-Report'!O34 -> 0 | G11: ='Daily-Report'!P34 -> 0 | H11: ='Daily-Report'!Q34 -> 0 | T11: Xalis artma (azalma) - AZN equal. | W11: =SUM(W3:W10) -> 0 | Y11: Xalis artma (azalma) - AZN equal. | AB11: =SUM(AB3:AB10) -> 0
A12: 11b | B12: Fiziki şəxslər | C12: =D12+E12+F12+G12+H12 -> 0 | D12: ='Daily-Report'!M35 -> 0 | E12: ='Daily-Report'!N35 -> 0 | F12: ='Daily-Report'!O35 -> 0 | G12: ='Daily-Report'!P35 -> 0 | H12: ='Daily-Report'!Q35 -> 0
A13: FERQ | O13: Xalis artma (azalma) - AZN equal. | R13: =SUM(R3:R12) -> 0
A14: PASSIVLƏR | C14: CƏMİ | D14: MANAT | E14: USD | F14: EURO | G14: RUBL | H14: DİGƏR
A15: 10a | B15: Hüquqi şəxslər | C15: =D15+E15+F15+G15+H15 -> 0 | D15: =D3-D9 -> 0 | E15: =E3-E9 -> 0 | F15: =F3-F9 -> 0 | G15: =G3-G9 -> 0 | H15: =H3-H9 -> 0
A16: 10b | B16: Fiziki şəxslər | C16: =D16+E16+F16+G16+H16 -> 0 | D16: =D4-D10 -> 0 | E16: =E4-E10 -> 0 | F16: =F4-F10 -> 0 | G16: =G4-G10 -> 0 | H16: =H4-H10 -> 0
A17: 11a | B17: Hüquqi şəxslər | C17: =D17+E17+F17+G17+H17 -> 0 | D17: =D5-D11 -> 0 | E17: =E5-E11 -> 0 | F17: =F5-F11 -> 0 | G17: =G5-G11 -> 0 | H17: =H5-H11 -> 0
A18: 11b | B18: Fiziki şəxslər | C18: =D18+E18+F18+G18+H18 -> 0 | D18: =D6-D12 -> 0 | E18: =E6-E12 -> 0 | F18: =F6-F12 -> 0 | G18: =G6-G12 -> 0 | H18: =H6-H12 -> 0
J34: Diger emeliyyatlar (<150k)
J56: Xalis artma (azalma) - AZN equal. | M56: =SUM(M3:M55) -> 0

Sheet 13
A1: ='Daily-Report'!A3 -> Tarix: 22/01/2024 | J1: Açıqlamalar aşağıdakı kimidir
A2: PASSİVLƏR | C2: CƏMİ | D2: MANAT | E2: USD | F2: EURO | G2: RUBL | H2: DİGƏR
A3: 13 | B3: Bankların tələbləri (Loro) | C3: =D3+E3+F3+G3+H3 -> 0 | D3: ='Daily-Report'!D37 -> 0 | E3: ='Daily-Report'!E37 -> 0 | F3: ='Daily-Report'!F37 -> 0 | G3: ='Daily-Report'!G37 -> 0 | H3: ='Daily-Report'!H37 -> 0 | J3: Musteri adi | K3: Valyutasi | L3: min AZN ekvivalentinde
A4: ='Daily-Report'!J3 -> Tarix 19/01/2024
A5: PASSİVLƏR | C5: CƏMİ | D5: MANAT | E5: USD | F5: EURO | G5: RUBL | H5: DİGƏR
A6: 13 | B6: Bankların tələbləri (Loro) | C6: =D6+E6+F6+G6+H6 -> 0 | D6: ='Daily-Report'!M37 -> 0 | E6: ='Daily-Report'!N37 -> 0 | F6: ='Daily-Report'!O37 -> 0 | G6: ='Daily-Report'!P37 -> 0 | H6: ='Daily-Report'!Q37 -> 0 | J6: Xalis artma (azalma) - AZN equal.
A8: FERQ
A9: PASSİVLƏR | C9: CƏMİ | D9: MANAT | E9: USD | F9: EURO | G9: RUBL | H9: DİGƏR
A10: 13 | B10: Bankların tələbləri (Loro) | C10: =D10+E10+F10+G10+H10 -> 0 | D10: =D3-D6 -> 0 | E10: =E3-E6 -> 0 | F10: =F3-F6 -> 0 | G10: =G3-G6 -> 0 | H10: =H3-H6 -> 0

Sheet 14
A1: ='Daily-Report'!A3 -> Tarix: 22/01/2024 | J1: Açıqlamalar aşağıdakı kimidir
A2: PASSİVLƏR | C2: CƏMİ | D2: MANAT | E2: USD | F2: EURO | G2: RUBL | H2: DİGƏR
A3: 14a | B3: Bankların depozitləri və kreditləri | C3: =D3+E3+F3+G3+H3 -> 0 | D3: ='Daily-Report'!D39 -> 0 | E3: ='Daily-Report'!E39 -> 0 | F3: ='Daily-Report'!F39 -> 0 | G3: ='Daily-Report'!G39 -> 0 | H3: ='Daily-Report'!H39 -> 0 | J3: Musteri adi | K3: Valyutasi | L3: min AZN ekvivalentinde
A4: ='Daily-Report'!J3 -> Tarix 19/01/2024
A5: PASSİVLƏR | C5: CƏMİ | D5: MANAT | E5: USD | F5: EURO | G5: RUBL | H5: DİGƏR
A6: 14a | B6: Bankların depozitləri və kreditləri | C6: =D6+E6+F6+G6+H6 -> 0 | D6: ='Daily-Report'!M39 -> 0 | E6: ='Daily-Report'!N39 -> 0 | F6: ='Daily-Report'!O39 -> 0 | G6: ='Daily-Report'!P39 -> 0 | H6: ='Daily-Report'!Q39 -> 0
A8: FERQ
A9: PASSİVLƏR | C9: CƏMİ | D9: MANAT | E9: USD | F9: EURO | G9: RUBL | H9: DİGƏR | J9: Xalis artma (azalma) - AZN equal. | L9: =SUM(L4:L8) -> 0
A10: 14a | B10: Bankların depozitləri və kreditləri | C10: =D10+E10+F10+G10+H10 -> 0 | D10: =D3-D6 -> 0 | E10: =E3-E6 -> 0 | F10: =F3-F6 -> 0 | G10: =G3-G6 -> 0 | H10: =H3-H6 -> 0
A13: =A1 -> Tarix: 22/01/2024
A14: PASSİVLƏR | C14: CƏMİ | D14: MANAT | E14: USD | F14: EURO | G14: RUBL | H14: DİGƏR
A15: 14c | B15: Maliyyə institutlarının depozitləri və kreditləri | C15: =D15+E15+F15+G15+H15 -> 0 | D15: ='Daily-Report'!D40 -> 0 | E15: ='Daily-Report'!E40 -> 0 | F15: ='Daily-Report'!F40 -> 0 | G15: ='Daily-Report'!G40 -> 0 | H15: ='Daily-Report'!H40 -> 0
A16: ='Daily-Report'!J3 -> Tarix 19/01/2024
A17: PASSİVLƏR | C17: CƏMİ | D17: MANAT | E17: USD | F17: EURO | G17: RUBL | H17: DİGƏR
A18: 14c | B18: Maliyyə institutlarının depozitləri və kreditləri | C18: =D18+E18+F18+G18+H18 -> 0 | D18: ='Daily-Report'!M40 -> 0 | E18: ='Daily-Report'!N40 -> 0 | F18: ='Daily-Report'!O40 -> 0 | G18: ='Daily-Report'!P40 -> 0 | H18: ='Daily-Report'!Q40 -> 0
A20: FERQ
A21: PASSİVLƏR | C21: CƏMİ | D21: MANAT | E21: USD | F21: EURO | G21: RUBL | H21: DİGƏR
A22: 14c | B22: Maliyyə institutlarının depozitləri və kreditləri | C22: =D22+E22+F22+G22+H22 -> 0 | D22: =D15-D18 -> 0 | E22: =E15-E18 -> 0 | F22: =F15-F18 -> 0 | G22: =G15-G18 -> 0 | H22: =H15-H18 -> 0
